{
 "cells": [
  {
   "cell_type": "code",
   "execution_count": 1,
   "id": "6cc2b44a",
   "metadata": {},
   "outputs": [],
   "source": [
    "import pandas as pd\n"
   ]
  },
  {
   "cell_type": "code",
   "execution_count": 2,
   "id": "0c20f9a9",
   "metadata": {},
   "outputs": [],
   "source": [
    "data = pd.read_csv('IdleTime_Pooled-Rides.csv',index_col=0)"
   ]
  },
  {
   "cell_type": "code",
   "execution_count": 3,
   "id": "fbb97bde",
   "metadata": {},
   "outputs": [
    {
     "data": {
      "text/html": [
       "<div>\n",
       "<style scoped>\n",
       "    .dataframe tbody tr th:only-of-type {\n",
       "        vertical-align: middle;\n",
       "    }\n",
       "\n",
       "    .dataframe tbody tr th {\n",
       "        vertical-align: top;\n",
       "    }\n",
       "\n",
       "    .dataframe thead th {\n",
       "        text-align: right;\n",
       "    }\n",
       "</style>\n",
       "<table border=\"1\" class=\"dataframe\">\n",
       "  <thead>\n",
       "    <tr style=\"text-align: right;\">\n",
       "      <th></th>\n",
       "      <th>100</th>\n",
       "      <th>200</th>\n",
       "      <th>300</th>\n",
       "      <th>400</th>\n",
       "      <th>500</th>\n",
       "    </tr>\n",
       "    <tr>\n",
       "      <th>0</th>\n",
       "      <th></th>\n",
       "      <th></th>\n",
       "      <th></th>\n",
       "      <th></th>\n",
       "      <th></th>\n",
       "    </tr>\n",
       "  </thead>\n",
       "  <tbody>\n",
       "    <tr>\n",
       "      <th>10</th>\n",
       "      <td>14241</td>\n",
       "      <td>17035</td>\n",
       "      <td>75562</td>\n",
       "      <td>75548</td>\n",
       "      <td>86473</td>\n",
       "    </tr>\n",
       "    <tr>\n",
       "      <th>20</th>\n",
       "      <td>174746</td>\n",
       "      <td>101241</td>\n",
       "      <td>42941</td>\n",
       "      <td>25200</td>\n",
       "      <td>45703</td>\n",
       "    </tr>\n",
       "    <tr>\n",
       "      <th>30</th>\n",
       "      <td>300898</td>\n",
       "      <td>300898</td>\n",
       "      <td>42941</td>\n",
       "      <td>138155</td>\n",
       "      <td>48291</td>\n",
       "    </tr>\n",
       "    <tr>\n",
       "      <th>40</th>\n",
       "      <td>566352</td>\n",
       "      <td>397584</td>\n",
       "      <td>337604</td>\n",
       "      <td>239711</td>\n",
       "      <td>166197</td>\n",
       "    </tr>\n",
       "    <tr>\n",
       "      <th>50</th>\n",
       "      <td>705246</td>\n",
       "      <td>610414</td>\n",
       "      <td>575554</td>\n",
       "      <td>421298</td>\n",
       "      <td>339779</td>\n",
       "    </tr>\n",
       "  </tbody>\n",
       "</table>\n",
       "</div>"
      ],
      "text/plain": [
       "       100     200     300     400     500\n",
       "0                                         \n",
       "10   14241   17035   75562   75548   86473\n",
       "20  174746  101241   42941   25200   45703\n",
       "30  300898  300898   42941  138155   48291\n",
       "40  566352  397584  337604  239711  166197\n",
       "50  705246  610414  575554  421298  339779"
      ]
     },
     "execution_count": 3,
     "metadata": {},
     "output_type": "execute_result"
    }
   ],
   "source": [
    "data.head()"
   ]
  },
  {
   "cell_type": "code",
   "execution_count": 4,
   "id": "7ac51282",
   "metadata": {},
   "outputs": [],
   "source": [
    "for col in data.columns:\n",
    "    data[col]=data[col]//60"
   ]
  },
  {
   "cell_type": "code",
   "execution_count": 20,
   "id": "759c7465",
   "metadata": {},
   "outputs": [
    {
     "data": {
      "text/html": [
       "<div>\n",
       "<style scoped>\n",
       "    .dataframe tbody tr th:only-of-type {\n",
       "        vertical-align: middle;\n",
       "    }\n",
       "\n",
       "    .dataframe tbody tr th {\n",
       "        vertical-align: top;\n",
       "    }\n",
       "\n",
       "    .dataframe thead th {\n",
       "        text-align: right;\n",
       "    }\n",
       "</style>\n",
       "<table border=\"1\" class=\"dataframe\">\n",
       "  <thead>\n",
       "    <tr style=\"text-align: right;\">\n",
       "      <th></th>\n",
       "      <th>100</th>\n",
       "      <th>200</th>\n",
       "      <th>300</th>\n",
       "      <th>400</th>\n",
       "      <th>500</th>\n",
       "    </tr>\n",
       "    <tr>\n",
       "      <th>0</th>\n",
       "      <th></th>\n",
       "      <th></th>\n",
       "      <th></th>\n",
       "      <th></th>\n",
       "      <th></th>\n",
       "    </tr>\n",
       "  </thead>\n",
       "  <tbody>\n",
       "    <tr>\n",
       "      <th>10</th>\n",
       "      <td>237</td>\n",
       "      <td>283</td>\n",
       "      <td>1259</td>\n",
       "      <td>1259</td>\n",
       "      <td>1441</td>\n",
       "    </tr>\n",
       "    <tr>\n",
       "      <th>20</th>\n",
       "      <td>2912</td>\n",
       "      <td>1687</td>\n",
       "      <td>715</td>\n",
       "      <td>420</td>\n",
       "      <td>761</td>\n",
       "    </tr>\n",
       "    <tr>\n",
       "      <th>30</th>\n",
       "      <td>5014</td>\n",
       "      <td>5014</td>\n",
       "      <td>715</td>\n",
       "      <td>2302</td>\n",
       "      <td>804</td>\n",
       "    </tr>\n",
       "    <tr>\n",
       "      <th>40</th>\n",
       "      <td>9439</td>\n",
       "      <td>6626</td>\n",
       "      <td>5626</td>\n",
       "      <td>3995</td>\n",
       "      <td>2769</td>\n",
       "    </tr>\n",
       "    <tr>\n",
       "      <th>50</th>\n",
       "      <td>11754</td>\n",
       "      <td>10173</td>\n",
       "      <td>9592</td>\n",
       "      <td>7021</td>\n",
       "      <td>5662</td>\n",
       "    </tr>\n",
       "  </tbody>\n",
       "</table>\n",
       "</div>"
      ],
      "text/plain": [
       "      100    200   300   400   500\n",
       "0                                 \n",
       "10    237    283  1259  1259  1441\n",
       "20   2912   1687   715   420   761\n",
       "30   5014   5014   715  2302   804\n",
       "40   9439   6626  5626  3995  2769\n",
       "50  11754  10173  9592  7021  5662"
      ]
     },
     "execution_count": 20,
     "metadata": {},
     "output_type": "execute_result"
    },
    {
     "name": "stderr",
     "output_type": "stream",
     "text": [
      "Exception in callback BaseSelectorEventLoop._read_from_self()\n",
      "handle: <Handle BaseSelectorEventLoop._read_from_self()>\n",
      "Traceback (most recent call last):\n",
      "  File \"C:\\Users\\shema\\anaconda3\\lib\\asyncio\\events.py\", line 80, in _run\n",
      "    self._context.run(self._callback, *self._args)\n",
      "  File \"C:\\Users\\shema\\anaconda3\\lib\\asyncio\\selector_events.py\", line 115, in _read_from_self\n",
      "    data = self._ssock.recv(4096)\n",
      "ConnectionResetError: [WinError 10054] An existing connection was forcibly closed by the remote host\n",
      "Exception in callback BaseSelectorEventLoop._read_from_self()\n",
      "handle: <Handle BaseSelectorEventLoop._read_from_self()>\n",
      "Traceback (most recent call last):\n",
      "  File \"C:\\Users\\shema\\anaconda3\\lib\\asyncio\\events.py\", line 80, in _run\n",
      "    self._context.run(self._callback, *self._args)\n",
      "  File \"C:\\Users\\shema\\anaconda3\\lib\\asyncio\\selector_events.py\", line 115, in _read_from_self\n",
      "    data = self._ssock.recv(4096)\n",
      "ConnectionResetError: [WinError 10054] An existing connection was forcibly closed by the remote host\n",
      "Exception in callback BaseSelectorEventLoop._read_from_self()\n",
      "handle: <Handle BaseSelectorEventLoop._read_from_self()>\n",
      "Traceback (most recent call last):\n",
      "  File \"C:\\Users\\shema\\anaconda3\\lib\\asyncio\\events.py\", line 80, in _run\n",
      "    self._context.run(self._callback, *self._args)\n",
      "  File \"C:\\Users\\shema\\anaconda3\\lib\\asyncio\\selector_events.py\", line 115, in _read_from_self\n",
      "    data = self._ssock.recv(4096)\n",
      "ConnectionResetError: [WinError 10054] An existing connection was forcibly closed by the remote host\n",
      "Exception in callback BaseSelectorEventLoop._read_from_self()\n",
      "handle: <Handle BaseSelectorEventLoop._read_from_self()>\n",
      "Traceback (most recent call last):\n",
      "  File \"C:\\Users\\shema\\anaconda3\\lib\\asyncio\\events.py\", line 80, in _run\n",
      "    self._context.run(self._callback, *self._args)\n",
      "  File \"C:\\Users\\shema\\anaconda3\\lib\\asyncio\\selector_events.py\", line 115, in _read_from_self\n",
      "    data = self._ssock.recv(4096)\n",
      "ConnectionResetError: [WinError 10054] An existing connection was forcibly closed by the remote host\n",
      "Exception in callback BaseSelectorEventLoop._read_from_self()\n",
      "handle: <Handle BaseSelectorEventLoop._read_from_self()>\n",
      "Traceback (most recent call last):\n",
      "  File \"C:\\Users\\shema\\anaconda3\\lib\\asyncio\\events.py\", line 80, in _run\n",
      "    self._context.run(self._callback, *self._args)\n",
      "  File \"C:\\Users\\shema\\anaconda3\\lib\\asyncio\\selector_events.py\", line 115, in _read_from_self\n",
      "    data = self._ssock.recv(4096)\n",
      "ConnectionResetError: [WinError 10054] An existing connection was forcibly closed by the remote host\n",
      "Exception in callback BaseSelectorEventLoop._read_from_self()\n",
      "handle: <Handle BaseSelectorEventLoop._read_from_self()>\n",
      "Traceback (most recent call last):\n",
      "  File \"C:\\Users\\shema\\anaconda3\\lib\\asyncio\\events.py\", line 80, in _run\n",
      "    self._context.run(self._callback, *self._args)\n",
      "  File \"C:\\Users\\shema\\anaconda3\\lib\\asyncio\\selector_events.py\", line 115, in _read_from_self\n",
      "    data = self._ssock.recv(4096)\n",
      "ConnectionResetError: [WinError 10054] An existing connection was forcibly closed by the remote host\n",
      "Exception in callback BaseSelectorEventLoop._read_from_self()\n",
      "handle: <Handle BaseSelectorEventLoop._read_from_self()>\n",
      "Traceback (most recent call last):\n",
      "  File \"C:\\Users\\shema\\anaconda3\\lib\\asyncio\\events.py\", line 80, in _run\n",
      "    self._context.run(self._callback, *self._args)\n",
      "  File \"C:\\Users\\shema\\anaconda3\\lib\\asyncio\\selector_events.py\", line 115, in _read_from_self\n",
      "    data = self._ssock.recv(4096)\n",
      "ConnectionResetError: [WinError 10054] An existing connection was forcibly closed by the remote host\n",
      "Exception in callback BaseSelectorEventLoop._read_from_self()\n",
      "handle: <Handle BaseSelectorEventLoop._read_from_self()>\n",
      "Traceback (most recent call last):\n",
      "  File \"C:\\Users\\shema\\anaconda3\\lib\\asyncio\\events.py\", line 80, in _run\n",
      "    self._context.run(self._callback, *self._args)\n",
      "  File \"C:\\Users\\shema\\anaconda3\\lib\\asyncio\\selector_events.py\", line 115, in _read_from_self\n",
      "    data = self._ssock.recv(4096)\n",
      "ConnectionResetError: [WinError 10054] An existing connection was forcibly closed by the remote host\n",
      "Exception in callback BaseSelectorEventLoop._read_from_self()\n",
      "handle: <Handle BaseSelectorEventLoop._read_from_self()>\n",
      "Traceback (most recent call last):\n",
      "  File \"C:\\Users\\shema\\anaconda3\\lib\\asyncio\\events.py\", line 80, in _run\n",
      "    self._context.run(self._callback, *self._args)\n",
      "  File \"C:\\Users\\shema\\anaconda3\\lib\\asyncio\\selector_events.py\", line 115, in _read_from_self\n",
      "    data = self._ssock.recv(4096)\n",
      "ConnectionResetError: [WinError 10054] An existing connection was forcibly closed by the remote host\n",
      "Exception in callback BaseSelectorEventLoop._read_from_self()\n",
      "handle: <Handle BaseSelectorEventLoop._read_from_self()>\n",
      "Traceback (most recent call last):\n",
      "  File \"C:\\Users\\shema\\anaconda3\\lib\\asyncio\\events.py\", line 80, in _run\n",
      "    self._context.run(self._callback, *self._args)\n",
      "  File \"C:\\Users\\shema\\anaconda3\\lib\\asyncio\\selector_events.py\", line 115, in _read_from_self\n",
      "    data = self._ssock.recv(4096)\n",
      "ConnectionResetError: [WinError 10054] An existing connection was forcibly closed by the remote host\n",
      "Exception in callback BaseSelectorEventLoop._read_from_self()\n",
      "handle: <Handle BaseSelectorEventLoop._read_from_self()>\n",
      "Traceback (most recent call last):\n",
      "  File \"C:\\Users\\shema\\anaconda3\\lib\\asyncio\\events.py\", line 80, in _run\n",
      "    self._context.run(self._callback, *self._args)\n",
      "  File \"C:\\Users\\shema\\anaconda3\\lib\\asyncio\\selector_events.py\", line 115, in _read_from_self\n",
      "    data = self._ssock.recv(4096)\n",
      "ConnectionResetError: [WinError 10054] An existing connection was forcibly closed by the remote host\n",
      "Exception in callback BaseSelectorEventLoop._read_from_self()\n",
      "handle: <Handle BaseSelectorEventLoop._read_from_self()>\n",
      "Traceback (most recent call last):\n",
      "  File \"C:\\Users\\shema\\anaconda3\\lib\\asyncio\\events.py\", line 80, in _run\n",
      "    self._context.run(self._callback, *self._args)\n",
      "  File \"C:\\Users\\shema\\anaconda3\\lib\\asyncio\\selector_events.py\", line 115, in _read_from_self\n",
      "    data = self._ssock.recv(4096)\n",
      "ConnectionResetError: [WinError 10054] An existing connection was forcibly closed by the remote host\n",
      "Exception in callback BaseSelectorEventLoop._read_from_self()\n",
      "handle: <Handle BaseSelectorEventLoop._read_from_self()>\n",
      "Traceback (most recent call last):\n",
      "  File \"C:\\Users\\shema\\anaconda3\\lib\\asyncio\\events.py\", line 80, in _run\n",
      "    self._context.run(self._callback, *self._args)\n",
      "  File \"C:\\Users\\shema\\anaconda3\\lib\\asyncio\\selector_events.py\", line 115, in _read_from_self\n",
      "    data = self._ssock.recv(4096)\n",
      "ConnectionResetError: [WinError 10054] An existing connection was forcibly closed by the remote host\n",
      "Exception in callback BaseSelectorEventLoop._read_from_self()\n",
      "handle: <Handle BaseSelectorEventLoop._read_from_self()>\n",
      "Traceback (most recent call last):\n",
      "  File \"C:\\Users\\shema\\anaconda3\\lib\\asyncio\\events.py\", line 80, in _run\n",
      "    self._context.run(self._callback, *self._args)\n",
      "  File \"C:\\Users\\shema\\anaconda3\\lib\\asyncio\\selector_events.py\", line 115, in _read_from_self\n",
      "    data = self._ssock.recv(4096)\n",
      "ConnectionResetError: [WinError 10054] An existing connection was forcibly closed by the remote host\n",
      "Exception in callback BaseSelectorEventLoop._read_from_self()\n",
      "handle: <Handle BaseSelectorEventLoop._read_from_self()>\n",
      "Traceback (most recent call last):\n",
      "  File \"C:\\Users\\shema\\anaconda3\\lib\\asyncio\\events.py\", line 80, in _run\n",
      "    self._context.run(self._callback, *self._args)\n",
      "  File \"C:\\Users\\shema\\anaconda3\\lib\\asyncio\\selector_events.py\", line 115, in _read_from_self\n",
      "    data = self._ssock.recv(4096)\n",
      "ConnectionResetError: [WinError 10054] An existing connection was forcibly closed by the remote host\n",
      "Exception in callback BaseSelectorEventLoop._read_from_self()\n",
      "handle: <Handle BaseSelectorEventLoop._read_from_self()>\n",
      "Traceback (most recent call last):\n",
      "  File \"C:\\Users\\shema\\anaconda3\\lib\\asyncio\\events.py\", line 80, in _run\n",
      "    self._context.run(self._callback, *self._args)\n",
      "  File \"C:\\Users\\shema\\anaconda3\\lib\\asyncio\\selector_events.py\", line 115, in _read_from_self\n",
      "    data = self._ssock.recv(4096)\n",
      "ConnectionResetError: [WinError 10054] An existing connection was forcibly closed by the remote host\n",
      "Exception in callback BaseSelectorEventLoop._read_from_self()\n",
      "handle: <Handle BaseSelectorEventLoop._read_from_self()>\n",
      "Traceback (most recent call last):\n",
      "  File \"C:\\Users\\shema\\anaconda3\\lib\\asyncio\\events.py\", line 80, in _run\n",
      "    self._context.run(self._callback, *self._args)\n",
      "  File \"C:\\Users\\shema\\anaconda3\\lib\\asyncio\\selector_events.py\", line 115, in _read_from_self\n",
      "    data = self._ssock.recv(4096)\n",
      "ConnectionResetError: [WinError 10054] An existing connection was forcibly closed by the remote host\n",
      "Exception in callback BaseSelectorEventLoop._read_from_self()\n",
      "handle: <Handle BaseSelectorEventLoop._read_from_self()>\n",
      "Traceback (most recent call last):\n",
      "  File \"C:\\Users\\shema\\anaconda3\\lib\\asyncio\\events.py\", line 80, in _run\n",
      "    self._context.run(self._callback, *self._args)\n",
      "  File \"C:\\Users\\shema\\anaconda3\\lib\\asyncio\\selector_events.py\", line 115, in _read_from_self\n",
      "    data = self._ssock.recv(4096)\n",
      "ConnectionResetError: [WinError 10054] An existing connection was forcibly closed by the remote host\n",
      "Exception in callback BaseSelectorEventLoop._read_from_self()\n",
      "handle: <Handle BaseSelectorEventLoop._read_from_self()>\n",
      "Traceback (most recent call last):\n",
      "  File \"C:\\Users\\shema\\anaconda3\\lib\\asyncio\\events.py\", line 80, in _run\n",
      "    self._context.run(self._callback, *self._args)\n",
      "  File \"C:\\Users\\shema\\anaconda3\\lib\\asyncio\\selector_events.py\", line 115, in _read_from_self\n",
      "    data = self._ssock.recv(4096)\n",
      "ConnectionResetError: [WinError 10054] An existing connection was forcibly closed by the remote host\n",
      "Exception in callback BaseSelectorEventLoop._read_from_self()\n",
      "handle: <Handle BaseSelectorEventLoop._read_from_self()>\n",
      "Traceback (most recent call last):\n",
      "  File \"C:\\Users\\shema\\anaconda3\\lib\\asyncio\\events.py\", line 80, in _run\n",
      "    self._context.run(self._callback, *self._args)\n",
      "  File \"C:\\Users\\shema\\anaconda3\\lib\\asyncio\\selector_events.py\", line 115, in _read_from_self\n",
      "    data = self._ssock.recv(4096)\n",
      "ConnectionResetError: [WinError 10054] An existing connection was forcibly closed by the remote host\n",
      "Exception in callback BaseSelectorEventLoop._read_from_self()\n",
      "handle: <Handle BaseSelectorEventLoop._read_from_self()>\n",
      "Traceback (most recent call last):\n",
      "  File \"C:\\Users\\shema\\anaconda3\\lib\\asyncio\\events.py\", line 80, in _run\n",
      "    self._context.run(self._callback, *self._args)\n",
      "  File \"C:\\Users\\shema\\anaconda3\\lib\\asyncio\\selector_events.py\", line 115, in _read_from_self\n",
      "    data = self._ssock.recv(4096)\n",
      "ConnectionResetError: [WinError 10054] An existing connection was forcibly closed by the remote host\n",
      "Exception in callback BaseSelectorEventLoop._read_from_self()\n",
      "handle: <Handle BaseSelectorEventLoop._read_from_self()>\n",
      "Traceback (most recent call last):\n",
      "  File \"C:\\Users\\shema\\anaconda3\\lib\\asyncio\\events.py\", line 80, in _run\n",
      "    self._context.run(self._callback, *self._args)\n",
      "  File \"C:\\Users\\shema\\anaconda3\\lib\\asyncio\\selector_events.py\", line 115, in _read_from_self\n",
      "    data = self._ssock.recv(4096)\n",
      "ConnectionResetError: [WinError 10054] An existing connection was forcibly closed by the remote host\n",
      "Exception in callback BaseSelectorEventLoop._read_from_self()\n",
      "handle: <Handle BaseSelectorEventLoop._read_from_self()>\n",
      "Traceback (most recent call last):\n",
      "  File \"C:\\Users\\shema\\anaconda3\\lib\\asyncio\\events.py\", line 80, in _run\n",
      "    self._context.run(self._callback, *self._args)\n",
      "  File \"C:\\Users\\shema\\anaconda3\\lib\\asyncio\\selector_events.py\", line 115, in _read_from_self\n",
      "    data = self._ssock.recv(4096)\n",
      "ConnectionResetError: [WinError 10054] An existing connection was forcibly closed by the remote host\n",
      "Exception in callback BaseSelectorEventLoop._read_from_self()\n",
      "handle: <Handle BaseSelectorEventLoop._read_from_self()>\n",
      "Traceback (most recent call last):\n",
      "  File \"C:\\Users\\shema\\anaconda3\\lib\\asyncio\\events.py\", line 80, in _run\n",
      "    self._context.run(self._callback, *self._args)\n",
      "  File \"C:\\Users\\shema\\anaconda3\\lib\\asyncio\\selector_events.py\", line 115, in _read_from_self\n",
      "    data = self._ssock.recv(4096)\n",
      "ConnectionResetError: [WinError 10054] An existing connection was forcibly closed by the remote host\n",
      "Exception in callback BaseSelectorEventLoop._read_from_self()\n",
      "handle: <Handle BaseSelectorEventLoop._read_from_self()>\n",
      "Traceback (most recent call last):\n",
      "  File \"C:\\Users\\shema\\anaconda3\\lib\\asyncio\\events.py\", line 80, in _run\n",
      "    self._context.run(self._callback, *self._args)\n",
      "  File \"C:\\Users\\shema\\anaconda3\\lib\\asyncio\\selector_events.py\", line 115, in _read_from_self\n",
      "    data = self._ssock.recv(4096)\n",
      "ConnectionResetError: [WinError 10054] An existing connection was forcibly closed by the remote host\n",
      "Exception in callback BaseSelectorEventLoop._read_from_self()\n",
      "handle: <Handle BaseSelectorEventLoop._read_from_self()>\n",
      "Traceback (most recent call last):\n",
      "  File \"C:\\Users\\shema\\anaconda3\\lib\\asyncio\\events.py\", line 80, in _run\n",
      "    self._context.run(self._callback, *self._args)\n",
      "  File \"C:\\Users\\shema\\anaconda3\\lib\\asyncio\\selector_events.py\", line 115, in _read_from_self\n",
      "    data = self._ssock.recv(4096)\n",
      "ConnectionResetError: [WinError 10054] An existing connection was forcibly closed by the remote host\n",
      "Exception in callback BaseSelectorEventLoop._read_from_self()\n",
      "handle: <Handle BaseSelectorEventLoop._read_from_self()>\n",
      "Traceback (most recent call last):\n",
      "  File \"C:\\Users\\shema\\anaconda3\\lib\\asyncio\\events.py\", line 80, in _run\n",
      "    self._context.run(self._callback, *self._args)\n",
      "  File \"C:\\Users\\shema\\anaconda3\\lib\\asyncio\\selector_events.py\", line 115, in _read_from_self\n",
      "    data = self._ssock.recv(4096)\n",
      "ConnectionResetError: [WinError 10054] An existing connection was forcibly closed by the remote host\n",
      "Exception in callback BaseSelectorEventLoop._read_from_self()\n",
      "handle: <Handle BaseSelectorEventLoop._read_from_self()>\n",
      "Traceback (most recent call last):\n",
      "  File \"C:\\Users\\shema\\anaconda3\\lib\\asyncio\\events.py\", line 80, in _run\n",
      "    self._context.run(self._callback, *self._args)\n",
      "  File \"C:\\Users\\shema\\anaconda3\\lib\\asyncio\\selector_events.py\", line 115, in _read_from_self\n",
      "    data = self._ssock.recv(4096)\n",
      "ConnectionResetError: [WinError 10054] An existing connection was forcibly closed by the remote host\n",
      "Exception in callback BaseSelectorEventLoop._read_from_self()\n",
      "handle: <Handle BaseSelectorEventLoop._read_from_self()>\n",
      "Traceback (most recent call last):\n",
      "  File \"C:\\Users\\shema\\anaconda3\\lib\\asyncio\\events.py\", line 80, in _run\n",
      "    self._context.run(self._callback, *self._args)\n",
      "  File \"C:\\Users\\shema\\anaconda3\\lib\\asyncio\\selector_events.py\", line 115, in _read_from_self\n",
      "    data = self._ssock.recv(4096)\n",
      "ConnectionResetError: [WinError 10054] An existing connection was forcibly closed by the remote host\n",
      "Exception in callback BaseSelectorEventLoop._read_from_self()\n",
      "handle: <Handle BaseSelectorEventLoop._read_from_self()>\n",
      "Traceback (most recent call last):\n",
      "  File \"C:\\Users\\shema\\anaconda3\\lib\\asyncio\\events.py\", line 80, in _run\n",
      "    self._context.run(self._callback, *self._args)\n",
      "  File \"C:\\Users\\shema\\anaconda3\\lib\\asyncio\\selector_events.py\", line 115, in _read_from_self\n",
      "    data = self._ssock.recv(4096)\n",
      "ConnectionResetError: [WinError 10054] An existing connection was forcibly closed by the remote host\n",
      "Exception in callback BaseSelectorEventLoop._read_from_self()\n",
      "handle: <Handle BaseSelectorEventLoop._read_from_self()>\n",
      "Traceback (most recent call last):\n",
      "  File \"C:\\Users\\shema\\anaconda3\\lib\\asyncio\\events.py\", line 80, in _run\n",
      "    self._context.run(self._callback, *self._args)\n",
      "  File \"C:\\Users\\shema\\anaconda3\\lib\\asyncio\\selector_events.py\", line 115, in _read_from_self\n",
      "    data = self._ssock.recv(4096)\n",
      "ConnectionResetError: [WinError 10054] An existing connection was forcibly closed by the remote host\n",
      "Exception in callback BaseSelectorEventLoop._read_from_self()\n",
      "handle: <Handle BaseSelectorEventLoop._read_from_self()>\n",
      "Traceback (most recent call last):\n",
      "  File \"C:\\Users\\shema\\anaconda3\\lib\\asyncio\\events.py\", line 80, in _run\n",
      "    self._context.run(self._callback, *self._args)\n",
      "  File \"C:\\Users\\shema\\anaconda3\\lib\\asyncio\\selector_events.py\", line 115, in _read_from_self\n",
      "    data = self._ssock.recv(4096)\n",
      "ConnectionResetError: [WinError 10054] An existing connection was forcibly closed by the remote host\n",
      "Exception in callback BaseSelectorEventLoop._read_from_self()\n",
      "handle: <Handle BaseSelectorEventLoop._read_from_self()>\n",
      "Traceback (most recent call last):\n",
      "  File \"C:\\Users\\shema\\anaconda3\\lib\\asyncio\\events.py\", line 80, in _run\n",
      "    self._context.run(self._callback, *self._args)\n",
      "  File \"C:\\Users\\shema\\anaconda3\\lib\\asyncio\\selector_events.py\", line 115, in _read_from_self\n",
      "    data = self._ssock.recv(4096)\n",
      "ConnectionResetError: [WinError 10054] An existing connection was forcibly closed by the remote host\n",
      "Exception in callback BaseSelectorEventLoop._read_from_self()\n",
      "handle: <Handle BaseSelectorEventLoop._read_from_self()>\n",
      "Traceback (most recent call last):\n",
      "  File \"C:\\Users\\shema\\anaconda3\\lib\\asyncio\\events.py\", line 80, in _run\n",
      "    self._context.run(self._callback, *self._args)\n",
      "  File \"C:\\Users\\shema\\anaconda3\\lib\\asyncio\\selector_events.py\", line 115, in _read_from_self\n",
      "    data = self._ssock.recv(4096)\n",
      "ConnectionResetError: [WinError 10054] An existing connection was forcibly closed by the remote host\n",
      "Exception in callback BaseSelectorEventLoop._read_from_self()\n",
      "handle: <Handle BaseSelectorEventLoop._read_from_self()>\n",
      "Traceback (most recent call last):\n",
      "  File \"C:\\Users\\shema\\anaconda3\\lib\\asyncio\\events.py\", line 80, in _run\n",
      "    self._context.run(self._callback, *self._args)\n",
      "  File \"C:\\Users\\shema\\anaconda3\\lib\\asyncio\\selector_events.py\", line 115, in _read_from_self\n",
      "    data = self._ssock.recv(4096)\n",
      "ConnectionResetError: [WinError 10054] An existing connection was forcibly closed by the remote host\n",
      "Exception in callback BaseSelectorEventLoop._read_from_self()\n",
      "handle: <Handle BaseSelectorEventLoop._read_from_self()>\n",
      "Traceback (most recent call last):\n",
      "  File \"C:\\Users\\shema\\anaconda3\\lib\\asyncio\\events.py\", line 80, in _run\n",
      "    self._context.run(self._callback, *self._args)\n",
      "  File \"C:\\Users\\shema\\anaconda3\\lib\\asyncio\\selector_events.py\", line 115, in _read_from_self\n",
      "    data = self._ssock.recv(4096)\n",
      "ConnectionResetError: [WinError 10054] An existing connection was forcibly closed by the remote host\n",
      "Exception in callback BaseSelectorEventLoop._read_from_self()\n",
      "handle: <Handle BaseSelectorEventLoop._read_from_self()>\n",
      "Traceback (most recent call last):\n",
      "  File \"C:\\Users\\shema\\anaconda3\\lib\\asyncio\\events.py\", line 80, in _run\n",
      "    self._context.run(self._callback, *self._args)\n",
      "  File \"C:\\Users\\shema\\anaconda3\\lib\\asyncio\\selector_events.py\", line 115, in _read_from_self\n",
      "    data = self._ssock.recv(4096)\n",
      "ConnectionResetError: [WinError 10054] An existing connection was forcibly closed by the remote host\n",
      "Exception in callback BaseSelectorEventLoop._read_from_self()\n",
      "handle: <Handle BaseSelectorEventLoop._read_from_self()>\n",
      "Traceback (most recent call last):\n",
      "  File \"C:\\Users\\shema\\anaconda3\\lib\\asyncio\\events.py\", line 80, in _run\n",
      "    self._context.run(self._callback, *self._args)\n",
      "  File \"C:\\Users\\shema\\anaconda3\\lib\\asyncio\\selector_events.py\", line 115, in _read_from_self\n",
      "    data = self._ssock.recv(4096)\n",
      "ConnectionResetError: [WinError 10054] An existing connection was forcibly closed by the remote host\n",
      "Exception in callback BaseSelectorEventLoop._read_from_self()\n",
      "handle: <Handle BaseSelectorEventLoop._read_from_self()>\n",
      "Traceback (most recent call last):\n",
      "  File \"C:\\Users\\shema\\anaconda3\\lib\\asyncio\\events.py\", line 80, in _run\n",
      "    self._context.run(self._callback, *self._args)\n",
      "  File \"C:\\Users\\shema\\anaconda3\\lib\\asyncio\\selector_events.py\", line 115, in _read_from_self\n",
      "    data = self._ssock.recv(4096)\n",
      "ConnectionResetError: [WinError 10054] An existing connection was forcibly closed by the remote host\n",
      "Exception in callback BaseSelectorEventLoop._read_from_self()\n",
      "handle: <Handle BaseSelectorEventLoop._read_from_self()>\n",
      "Traceback (most recent call last):\n",
      "  File \"C:\\Users\\shema\\anaconda3\\lib\\asyncio\\events.py\", line 80, in _run\n",
      "    self._context.run(self._callback, *self._args)\n",
      "  File \"C:\\Users\\shema\\anaconda3\\lib\\asyncio\\selector_events.py\", line 115, in _read_from_self\n",
      "    data = self._ssock.recv(4096)\n",
      "ConnectionResetError: [WinError 10054] An existing connection was forcibly closed by the remote host\n",
      "Exception in callback BaseSelectorEventLoop._read_from_self()\n",
      "handle: <Handle BaseSelectorEventLoop._read_from_self()>\n",
      "Traceback (most recent call last):\n",
      "  File \"C:\\Users\\shema\\anaconda3\\lib\\asyncio\\events.py\", line 80, in _run\n",
      "    self._context.run(self._callback, *self._args)\n",
      "  File \"C:\\Users\\shema\\anaconda3\\lib\\asyncio\\selector_events.py\", line 115, in _read_from_self\n",
      "    data = self._ssock.recv(4096)\n",
      "ConnectionResetError: [WinError 10054] An existing connection was forcibly closed by the remote host\n",
      "Exception in callback BaseSelectorEventLoop._read_from_self()\n",
      "handle: <Handle BaseSelectorEventLoop._read_from_self()>\n",
      "Traceback (most recent call last):\n",
      "  File \"C:\\Users\\shema\\anaconda3\\lib\\asyncio\\events.py\", line 80, in _run\n",
      "    self._context.run(self._callback, *self._args)\n",
      "  File \"C:\\Users\\shema\\anaconda3\\lib\\asyncio\\selector_events.py\", line 115, in _read_from_self\n",
      "    data = self._ssock.recv(4096)\n",
      "ConnectionResetError: [WinError 10054] An existing connection was forcibly closed by the remote host\n",
      "Exception in callback BaseSelectorEventLoop._read_from_self()\n",
      "handle: <Handle BaseSelectorEventLoop._read_from_self()>\n",
      "Traceback (most recent call last):\n",
      "  File \"C:\\Users\\shema\\anaconda3\\lib\\asyncio\\events.py\", line 80, in _run\n",
      "    self._context.run(self._callback, *self._args)\n",
      "  File \"C:\\Users\\shema\\anaconda3\\lib\\asyncio\\selector_events.py\", line 115, in _read_from_self\n",
      "    data = self._ssock.recv(4096)\n",
      "ConnectionResetError: [WinError 10054] An existing connection was forcibly closed by the remote host\n",
      "Exception in callback BaseSelectorEventLoop._read_from_self()\n",
      "handle: <Handle BaseSelectorEventLoop._read_from_self()>\n",
      "Traceback (most recent call last):\n",
      "  File \"C:\\Users\\shema\\anaconda3\\lib\\asyncio\\events.py\", line 80, in _run\n",
      "    self._context.run(self._callback, *self._args)\n",
      "  File \"C:\\Users\\shema\\anaconda3\\lib\\asyncio\\selector_events.py\", line 115, in _read_from_self\n",
      "    data = self._ssock.recv(4096)\n",
      "ConnectionResetError: [WinError 10054] An existing connection was forcibly closed by the remote host\n",
      "Exception in callback BaseSelectorEventLoop._read_from_self()\n",
      "handle: <Handle BaseSelectorEventLoop._read_from_self()>\n",
      "Traceback (most recent call last):\n",
      "  File \"C:\\Users\\shema\\anaconda3\\lib\\asyncio\\events.py\", line 80, in _run\n",
      "    self._context.run(self._callback, *self._args)\n",
      "  File \"C:\\Users\\shema\\anaconda3\\lib\\asyncio\\selector_events.py\", line 115, in _read_from_self\n",
      "    data = self._ssock.recv(4096)\n",
      "ConnectionResetError: [WinError 10054] An existing connection was forcibly closed by the remote host\n",
      "Exception in callback BaseSelectorEventLoop._read_from_self()\n",
      "handle: <Handle BaseSelectorEventLoop._read_from_self()>\n",
      "Traceback (most recent call last):\n",
      "  File \"C:\\Users\\shema\\anaconda3\\lib\\asyncio\\events.py\", line 80, in _run\n",
      "    self._context.run(self._callback, *self._args)\n",
      "  File \"C:\\Users\\shema\\anaconda3\\lib\\asyncio\\selector_events.py\", line 115, in _read_from_self\n",
      "    data = self._ssock.recv(4096)\n",
      "ConnectionResetError: [WinError 10054] An existing connection was forcibly closed by the remote host\n",
      "Exception in callback BaseSelectorEventLoop._read_from_self()\n",
      "handle: <Handle BaseSelectorEventLoop._read_from_self()>\n",
      "Traceback (most recent call last):\n",
      "  File \"C:\\Users\\shema\\anaconda3\\lib\\asyncio\\events.py\", line 80, in _run\n",
      "    self._context.run(self._callback, *self._args)\n",
      "  File \"C:\\Users\\shema\\anaconda3\\lib\\asyncio\\selector_events.py\", line 115, in _read_from_self\n",
      "    data = self._ssock.recv(4096)\n",
      "ConnectionResetError: [WinError 10054] An existing connection was forcibly closed by the remote host\n",
      "Exception in callback BaseSelectorEventLoop._read_from_self()\n",
      "handle: <Handle BaseSelectorEventLoop._read_from_self()>\n",
      "Traceback (most recent call last):\n",
      "  File \"C:\\Users\\shema\\anaconda3\\lib\\asyncio\\events.py\", line 80, in _run\n",
      "    self._context.run(self._callback, *self._args)\n",
      "  File \"C:\\Users\\shema\\anaconda3\\lib\\asyncio\\selector_events.py\", line 115, in _read_from_self\n",
      "    data = self._ssock.recv(4096)\n",
      "ConnectionResetError: [WinError 10054] An existing connection was forcibly closed by the remote host\n",
      "Exception in callback BaseSelectorEventLoop._read_from_self()\n",
      "handle: <Handle BaseSelectorEventLoop._read_from_self()>\n",
      "Traceback (most recent call last):\n",
      "  File \"C:\\Users\\shema\\anaconda3\\lib\\asyncio\\events.py\", line 80, in _run\n",
      "    self._context.run(self._callback, *self._args)\n",
      "  File \"C:\\Users\\shema\\anaconda3\\lib\\asyncio\\selector_events.py\", line 115, in _read_from_self\n",
      "    data = self._ssock.recv(4096)\n",
      "ConnectionResetError: [WinError 10054] An existing connection was forcibly closed by the remote host\n",
      "Exception in callback BaseSelectorEventLoop._read_from_self()\n",
      "handle: <Handle BaseSelectorEventLoop._read_from_self()>\n",
      "Traceback (most recent call last):\n",
      "  File \"C:\\Users\\shema\\anaconda3\\lib\\asyncio\\events.py\", line 80, in _run\n",
      "    self._context.run(self._callback, *self._args)\n",
      "  File \"C:\\Users\\shema\\anaconda3\\lib\\asyncio\\selector_events.py\", line 115, in _read_from_self\n",
      "    data = self._ssock.recv(4096)\n",
      "ConnectionResetError: [WinError 10054] An existing connection was forcibly closed by the remote host\n",
      "Exception in callback BaseSelectorEventLoop._read_from_self()\n",
      "handle: <Handle BaseSelectorEventLoop._read_from_self()>\n",
      "Traceback (most recent call last):\n",
      "  File \"C:\\Users\\shema\\anaconda3\\lib\\asyncio\\events.py\", line 80, in _run\n",
      "    self._context.run(self._callback, *self._args)\n",
      "  File \"C:\\Users\\shema\\anaconda3\\lib\\asyncio\\selector_events.py\", line 115, in _read_from_self\n",
      "    data = self._ssock.recv(4096)\n",
      "ConnectionResetError: [WinError 10054] An existing connection was forcibly closed by the remote host\n",
      "Exception in callback BaseSelectorEventLoop._read_from_self()\n",
      "handle: <Handle BaseSelectorEventLoop._read_from_self()>\n",
      "Traceback (most recent call last):\n",
      "  File \"C:\\Users\\shema\\anaconda3\\lib\\asyncio\\events.py\", line 80, in _run\n",
      "    self._context.run(self._callback, *self._args)\n",
      "  File \"C:\\Users\\shema\\anaconda3\\lib\\asyncio\\selector_events.py\", line 115, in _read_from_self\n",
      "    data = self._ssock.recv(4096)\n",
      "ConnectionResetError: [WinError 10054] An existing connection was forcibly closed by the remote host\n",
      "Exception in callback BaseSelectorEventLoop._read_from_self()\n",
      "handle: <Handle BaseSelectorEventLoop._read_from_self()>\n",
      "Traceback (most recent call last):\n",
      "  File \"C:\\Users\\shema\\anaconda3\\lib\\asyncio\\events.py\", line 80, in _run\n",
      "    self._context.run(self._callback, *self._args)\n",
      "  File \"C:\\Users\\shema\\anaconda3\\lib\\asyncio\\selector_events.py\", line 115, in _read_from_self\n",
      "    data = self._ssock.recv(4096)\n",
      "ConnectionResetError: [WinError 10054] An existing connection was forcibly closed by the remote host\n",
      "Exception in callback BaseSelectorEventLoop._read_from_self()\n",
      "handle: <Handle BaseSelectorEventLoop._read_from_self()>\n",
      "Traceback (most recent call last):\n",
      "  File \"C:\\Users\\shema\\anaconda3\\lib\\asyncio\\events.py\", line 80, in _run\n",
      "    self._context.run(self._callback, *self._args)\n",
      "  File \"C:\\Users\\shema\\anaconda3\\lib\\asyncio\\selector_events.py\", line 115, in _read_from_self\n",
      "    data = self._ssock.recv(4096)\n",
      "ConnectionResetError: [WinError 10054] An existing connection was forcibly closed by the remote host\n",
      "Exception in callback BaseSelectorEventLoop._read_from_self()\n",
      "handle: <Handle BaseSelectorEventLoop._read_from_self()>\n",
      "Traceback (most recent call last):\n",
      "  File \"C:\\Users\\shema\\anaconda3\\lib\\asyncio\\events.py\", line 80, in _run\n",
      "    self._context.run(self._callback, *self._args)\n",
      "  File \"C:\\Users\\shema\\anaconda3\\lib\\asyncio\\selector_events.py\", line 115, in _read_from_self\n",
      "    data = self._ssock.recv(4096)\n",
      "ConnectionResetError: [WinError 10054] An existing connection was forcibly closed by the remote host\n",
      "Exception in callback BaseSelectorEventLoop._read_from_self()\n",
      "handle: <Handle BaseSelectorEventLoop._read_from_self()>\n",
      "Traceback (most recent call last):\n",
      "  File \"C:\\Users\\shema\\anaconda3\\lib\\asyncio\\events.py\", line 80, in _run\n",
      "    self._context.run(self._callback, *self._args)\n",
      "  File \"C:\\Users\\shema\\anaconda3\\lib\\asyncio\\selector_events.py\", line 115, in _read_from_self\n",
      "    data = self._ssock.recv(4096)\n",
      "ConnectionResetError: [WinError 10054] An existing connection was forcibly closed by the remote host\n",
      "Exception in callback BaseSelectorEventLoop._read_from_self()\n",
      "handle: <Handle BaseSelectorEventLoop._read_from_self()>\n",
      "Traceback (most recent call last):\n",
      "  File \"C:\\Users\\shema\\anaconda3\\lib\\asyncio\\events.py\", line 80, in _run\n",
      "    self._context.run(self._callback, *self._args)\n",
      "  File \"C:\\Users\\shema\\anaconda3\\lib\\asyncio\\selector_events.py\", line 115, in _read_from_self\n",
      "    data = self._ssock.recv(4096)\n",
      "ConnectionResetError: [WinError 10054] An existing connection was forcibly closed by the remote host\n",
      "Exception in callback BaseSelectorEventLoop._read_from_self()\n",
      "handle: <Handle BaseSelectorEventLoop._read_from_self()>\n",
      "Traceback (most recent call last):\n",
      "  File \"C:\\Users\\shema\\anaconda3\\lib\\asyncio\\events.py\", line 80, in _run\n",
      "    self._context.run(self._callback, *self._args)\n",
      "  File \"C:\\Users\\shema\\anaconda3\\lib\\asyncio\\selector_events.py\", line 115, in _read_from_self\n",
      "    data = self._ssock.recv(4096)\n",
      "ConnectionResetError: [WinError 10054] An existing connection was forcibly closed by the remote host\n",
      "Exception in callback BaseSelectorEventLoop._read_from_self()\n",
      "handle: <Handle BaseSelectorEventLoop._read_from_self()>\n",
      "Traceback (most recent call last):\n",
      "  File \"C:\\Users\\shema\\anaconda3\\lib\\asyncio\\events.py\", line 80, in _run\n",
      "    self._context.run(self._callback, *self._args)\n",
      "  File \"C:\\Users\\shema\\anaconda3\\lib\\asyncio\\selector_events.py\", line 115, in _read_from_self\n",
      "    data = self._ssock.recv(4096)\n",
      "ConnectionResetError: [WinError 10054] An existing connection was forcibly closed by the remote host\n",
      "Exception in callback BaseSelectorEventLoop._read_from_self()\n",
      "handle: <Handle BaseSelectorEventLoop._read_from_self()>\n",
      "Traceback (most recent call last):\n",
      "  File \"C:\\Users\\shema\\anaconda3\\lib\\asyncio\\events.py\", line 80, in _run\n",
      "    self._context.run(self._callback, *self._args)\n",
      "  File \"C:\\Users\\shema\\anaconda3\\lib\\asyncio\\selector_events.py\", line 115, in _read_from_self\n",
      "    data = self._ssock.recv(4096)\n",
      "ConnectionResetError: [WinError 10054] An existing connection was forcibly closed by the remote host\n",
      "Exception in callback BaseSelectorEventLoop._read_from_self()\n",
      "handle: <Handle BaseSelectorEventLoop._read_from_self()>\n",
      "Traceback (most recent call last):\n",
      "  File \"C:\\Users\\shema\\anaconda3\\lib\\asyncio\\events.py\", line 80, in _run\n",
      "    self._context.run(self._callback, *self._args)\n",
      "  File \"C:\\Users\\shema\\anaconda3\\lib\\asyncio\\selector_events.py\", line 115, in _read_from_self\n",
      "    data = self._ssock.recv(4096)\n",
      "ConnectionResetError: [WinError 10054] An existing connection was forcibly closed by the remote host\n",
      "Exception in callback BaseSelectorEventLoop._read_from_self()\n",
      "handle: <Handle BaseSelectorEventLoop._read_from_self()>\n",
      "Traceback (most recent call last):\n",
      "  File \"C:\\Users\\shema\\anaconda3\\lib\\asyncio\\events.py\", line 80, in _run\n",
      "    self._context.run(self._callback, *self._args)\n",
      "  File \"C:\\Users\\shema\\anaconda3\\lib\\asyncio\\selector_events.py\", line 115, in _read_from_self\n",
      "    data = self._ssock.recv(4096)\n",
      "ConnectionResetError: [WinError 10054] An existing connection was forcibly closed by the remote host\n",
      "Exception in callback BaseSelectorEventLoop._read_from_self()\n",
      "handle: <Handle BaseSelectorEventLoop._read_from_self()>\n",
      "Traceback (most recent call last):\n",
      "  File \"C:\\Users\\shema\\anaconda3\\lib\\asyncio\\events.py\", line 80, in _run\n",
      "    self._context.run(self._callback, *self._args)\n",
      "  File \"C:\\Users\\shema\\anaconda3\\lib\\asyncio\\selector_events.py\", line 115, in _read_from_self\n",
      "    data = self._ssock.recv(4096)\n",
      "ConnectionResetError: [WinError 10054] An existing connection was forcibly closed by the remote host\n",
      "Exception in callback BaseSelectorEventLoop._read_from_self()\n",
      "handle: <Handle BaseSelectorEventLoop._read_from_self()>\n",
      "Traceback (most recent call last):\n",
      "  File \"C:\\Users\\shema\\anaconda3\\lib\\asyncio\\events.py\", line 80, in _run\n",
      "    self._context.run(self._callback, *self._args)\n",
      "  File \"C:\\Users\\shema\\anaconda3\\lib\\asyncio\\selector_events.py\", line 115, in _read_from_self\n",
      "    data = self._ssock.recv(4096)\n",
      "ConnectionResetError: [WinError 10054] An existing connection was forcibly closed by the remote host\n",
      "Exception in callback BaseSelectorEventLoop._read_from_self()\n",
      "handle: <Handle BaseSelectorEventLoop._read_from_self()>\n",
      "Traceback (most recent call last):\n",
      "  File \"C:\\Users\\shema\\anaconda3\\lib\\asyncio\\events.py\", line 80, in _run\n",
      "    self._context.run(self._callback, *self._args)\n",
      "  File \"C:\\Users\\shema\\anaconda3\\lib\\asyncio\\selector_events.py\", line 115, in _read_from_self\n",
      "    data = self._ssock.recv(4096)\n",
      "ConnectionResetError: [WinError 10054] An existing connection was forcibly closed by the remote host\n",
      "Exception in callback BaseSelectorEventLoop._read_from_self()\n",
      "handle: <Handle BaseSelectorEventLoop._read_from_self()>\n",
      "Traceback (most recent call last):\n",
      "  File \"C:\\Users\\shema\\anaconda3\\lib\\asyncio\\events.py\", line 80, in _run\n",
      "    self._context.run(self._callback, *self._args)\n",
      "  File \"C:\\Users\\shema\\anaconda3\\lib\\asyncio\\selector_events.py\", line 115, in _read_from_self\n",
      "    data = self._ssock.recv(4096)\n",
      "ConnectionResetError: [WinError 10054] An existing connection was forcibly closed by the remote host\n",
      "Exception in callback BaseSelectorEventLoop._read_from_self()\n",
      "handle: <Handle BaseSelectorEventLoop._read_from_self()>\n",
      "Traceback (most recent call last):\n",
      "  File \"C:\\Users\\shema\\anaconda3\\lib\\asyncio\\events.py\", line 80, in _run\n",
      "    self._context.run(self._callback, *self._args)\n",
      "  File \"C:\\Users\\shema\\anaconda3\\lib\\asyncio\\selector_events.py\", line 115, in _read_from_self\n",
      "    data = self._ssock.recv(4096)\n",
      "ConnectionResetError: [WinError 10054] An existing connection was forcibly closed by the remote host\n",
      "Exception in callback BaseSelectorEventLoop._read_from_self()\n",
      "handle: <Handle BaseSelectorEventLoop._read_from_self()>\n",
      "Traceback (most recent call last):\n",
      "  File \"C:\\Users\\shema\\anaconda3\\lib\\asyncio\\events.py\", line 80, in _run\n",
      "    self._context.run(self._callback, *self._args)\n",
      "  File \"C:\\Users\\shema\\anaconda3\\lib\\asyncio\\selector_events.py\", line 115, in _read_from_self\n",
      "    data = self._ssock.recv(4096)\n",
      "ConnectionResetError: [WinError 10054] An existing connection was forcibly closed by the remote host\n",
      "Exception in callback BaseSelectorEventLoop._read_from_self()\n",
      "handle: <Handle BaseSelectorEventLoop._read_from_self()>\n",
      "Traceback (most recent call last):\n",
      "  File \"C:\\Users\\shema\\anaconda3\\lib\\asyncio\\events.py\", line 80, in _run\n",
      "    self._context.run(self._callback, *self._args)\n",
      "  File \"C:\\Users\\shema\\anaconda3\\lib\\asyncio\\selector_events.py\", line 115, in _read_from_self\n",
      "    data = self._ssock.recv(4096)\n",
      "ConnectionResetError: [WinError 10054] An existing connection was forcibly closed by the remote host\n",
      "Exception in callback BaseSelectorEventLoop._read_from_self()\n",
      "handle: <Handle BaseSelectorEventLoop._read_from_self()>\n",
      "Traceback (most recent call last):\n",
      "  File \"C:\\Users\\shema\\anaconda3\\lib\\asyncio\\events.py\", line 80, in _run\n",
      "    self._context.run(self._callback, *self._args)\n",
      "  File \"C:\\Users\\shema\\anaconda3\\lib\\asyncio\\selector_events.py\", line 115, in _read_from_self\n",
      "    data = self._ssock.recv(4096)\n",
      "ConnectionResetError: [WinError 10054] An existing connection was forcibly closed by the remote host\n",
      "Exception in callback BaseSelectorEventLoop._read_from_self()\n",
      "handle: <Handle BaseSelectorEventLoop._read_from_self()>\n",
      "Traceback (most recent call last):\n",
      "  File \"C:\\Users\\shema\\anaconda3\\lib\\asyncio\\events.py\", line 80, in _run\n",
      "    self._context.run(self._callback, *self._args)\n",
      "  File \"C:\\Users\\shema\\anaconda3\\lib\\asyncio\\selector_events.py\", line 115, in _read_from_self\n",
      "    data = self._ssock.recv(4096)\n",
      "ConnectionResetError: [WinError 10054] An existing connection was forcibly closed by the remote host\n",
      "Exception in callback BaseSelectorEventLoop._read_from_self()\n",
      "handle: <Handle BaseSelectorEventLoop._read_from_self()>\n",
      "Traceback (most recent call last):\n",
      "  File \"C:\\Users\\shema\\anaconda3\\lib\\asyncio\\events.py\", line 80, in _run\n",
      "    self._context.run(self._callback, *self._args)\n",
      "  File \"C:\\Users\\shema\\anaconda3\\lib\\asyncio\\selector_events.py\", line 115, in _read_from_self\n",
      "    data = self._ssock.recv(4096)\n",
      "ConnectionResetError: [WinError 10054] An existing connection was forcibly closed by the remote host\n",
      "Exception in callback BaseSelectorEventLoop._read_from_self()\n",
      "handle: <Handle BaseSelectorEventLoop._read_from_self()>\n",
      "Traceback (most recent call last):\n",
      "  File \"C:\\Users\\shema\\anaconda3\\lib\\asyncio\\events.py\", line 80, in _run\n",
      "    self._context.run(self._callback, *self._args)\n",
      "  File \"C:\\Users\\shema\\anaconda3\\lib\\asyncio\\selector_events.py\", line 115, in _read_from_self\n",
      "    data = self._ssock.recv(4096)\n",
      "ConnectionResetError: [WinError 10054] An existing connection was forcibly closed by the remote host\n",
      "Exception in callback BaseSelectorEventLoop._read_from_self()\n",
      "handle: <Handle BaseSelectorEventLoop._read_from_self()>\n",
      "Traceback (most recent call last):\n",
      "  File \"C:\\Users\\shema\\anaconda3\\lib\\asyncio\\events.py\", line 80, in _run\n",
      "    self._context.run(self._callback, *self._args)\n",
      "  File \"C:\\Users\\shema\\anaconda3\\lib\\asyncio\\selector_events.py\", line 115, in _read_from_self\n",
      "    data = self._ssock.recv(4096)\n",
      "ConnectionResetError: [WinError 10054] An existing connection was forcibly closed by the remote host\n",
      "Exception in callback BaseSelectorEventLoop._read_from_self()\n",
      "handle: <Handle BaseSelectorEventLoop._read_from_self()>\n",
      "Traceback (most recent call last):\n",
      "  File \"C:\\Users\\shema\\anaconda3\\lib\\asyncio\\events.py\", line 80, in _run\n",
      "    self._context.run(self._callback, *self._args)\n",
      "  File \"C:\\Users\\shema\\anaconda3\\lib\\asyncio\\selector_events.py\", line 115, in _read_from_self\n",
      "    data = self._ssock.recv(4096)\n",
      "ConnectionResetError: [WinError 10054] An existing connection was forcibly closed by the remote host\n",
      "Exception in callback BaseSelectorEventLoop._read_from_self()\n",
      "handle: <Handle BaseSelectorEventLoop._read_from_self()>\n",
      "Traceback (most recent call last):\n",
      "  File \"C:\\Users\\shema\\anaconda3\\lib\\asyncio\\events.py\", line 80, in _run\n",
      "    self._context.run(self._callback, *self._args)\n",
      "  File \"C:\\Users\\shema\\anaconda3\\lib\\asyncio\\selector_events.py\", line 115, in _read_from_self\n",
      "    data = self._ssock.recv(4096)\n",
      "ConnectionResetError: [WinError 10054] An existing connection was forcibly closed by the remote host\n",
      "Exception in callback BaseSelectorEventLoop._read_from_self()\n",
      "handle: <Handle BaseSelectorEventLoop._read_from_self()>\n",
      "Traceback (most recent call last):\n",
      "  File \"C:\\Users\\shema\\anaconda3\\lib\\asyncio\\events.py\", line 80, in _run\n",
      "    self._context.run(self._callback, *self._args)\n",
      "  File \"C:\\Users\\shema\\anaconda3\\lib\\asyncio\\selector_events.py\", line 115, in _read_from_self\n",
      "    data = self._ssock.recv(4096)\n",
      "ConnectionResetError: [WinError 10054] An existing connection was forcibly closed by the remote host\n",
      "Exception in callback BaseSelectorEventLoop._read_from_self()\n",
      "handle: <Handle BaseSelectorEventLoop._read_from_self()>\n",
      "Traceback (most recent call last):\n",
      "  File \"C:\\Users\\shema\\anaconda3\\lib\\asyncio\\events.py\", line 80, in _run\n",
      "    self._context.run(self._callback, *self._args)\n",
      "  File \"C:\\Users\\shema\\anaconda3\\lib\\asyncio\\selector_events.py\", line 115, in _read_from_self\n",
      "    data = self._ssock.recv(4096)\n",
      "ConnectionResetError: [WinError 10054] An existing connection was forcibly closed by the remote host\n",
      "Exception in callback BaseSelectorEventLoop._read_from_self()\n",
      "handle: <Handle BaseSelectorEventLoop._read_from_self()>\n",
      "Traceback (most recent call last):\n",
      "  File \"C:\\Users\\shema\\anaconda3\\lib\\asyncio\\events.py\", line 80, in _run\n",
      "    self._context.run(self._callback, *self._args)\n",
      "  File \"C:\\Users\\shema\\anaconda3\\lib\\asyncio\\selector_events.py\", line 115, in _read_from_self\n",
      "    data = self._ssock.recv(4096)\n",
      "ConnectionResetError: [WinError 10054] An existing connection was forcibly closed by the remote host\n",
      "Exception in callback BaseSelectorEventLoop._read_from_self()\n",
      "handle: <Handle BaseSelectorEventLoop._read_from_self()>\n",
      "Traceback (most recent call last):\n",
      "  File \"C:\\Users\\shema\\anaconda3\\lib\\asyncio\\events.py\", line 80, in _run\n",
      "    self._context.run(self._callback, *self._args)\n",
      "  File \"C:\\Users\\shema\\anaconda3\\lib\\asyncio\\selector_events.py\", line 115, in _read_from_self\n",
      "    data = self._ssock.recv(4096)\n",
      "ConnectionResetError: [WinError 10054] An existing connection was forcibly closed by the remote host\n",
      "Exception in callback BaseSelectorEventLoop._read_from_self()\n",
      "handle: <Handle BaseSelectorEventLoop._read_from_self()>\n",
      "Traceback (most recent call last):\n",
      "  File \"C:\\Users\\shema\\anaconda3\\lib\\asyncio\\events.py\", line 80, in _run\n",
      "    self._context.run(self._callback, *self._args)\n",
      "  File \"C:\\Users\\shema\\anaconda3\\lib\\asyncio\\selector_events.py\", line 115, in _read_from_self\n",
      "    data = self._ssock.recv(4096)\n",
      "ConnectionResetError: [WinError 10054] An existing connection was forcibly closed by the remote host\n",
      "Exception in callback BaseSelectorEventLoop._read_from_self()\n",
      "handle: <Handle BaseSelectorEventLoop._read_from_self()>\n",
      "Traceback (most recent call last):\n",
      "  File \"C:\\Users\\shema\\anaconda3\\lib\\asyncio\\events.py\", line 80, in _run\n",
      "    self._context.run(self._callback, *self._args)\n",
      "  File \"C:\\Users\\shema\\anaconda3\\lib\\asyncio\\selector_events.py\", line 115, in _read_from_self\n",
      "    data = self._ssock.recv(4096)\n",
      "ConnectionResetError: [WinError 10054] An existing connection was forcibly closed by the remote host\n",
      "Exception in callback BaseSelectorEventLoop._read_from_self()\n",
      "handle: <Handle BaseSelectorEventLoop._read_from_self()>\n",
      "Traceback (most recent call last):\n",
      "  File \"C:\\Users\\shema\\anaconda3\\lib\\asyncio\\events.py\", line 80, in _run\n",
      "    self._context.run(self._callback, *self._args)\n",
      "  File \"C:\\Users\\shema\\anaconda3\\lib\\asyncio\\selector_events.py\", line 115, in _read_from_self\n",
      "    data = self._ssock.recv(4096)\n",
      "ConnectionResetError: [WinError 10054] An existing connection was forcibly closed by the remote host\n",
      "Exception in callback BaseSelectorEventLoop._read_from_self()\n",
      "handle: <Handle BaseSelectorEventLoop._read_from_self()>\n",
      "Traceback (most recent call last):\n",
      "  File \"C:\\Users\\shema\\anaconda3\\lib\\asyncio\\events.py\", line 80, in _run\n",
      "    self._context.run(self._callback, *self._args)\n",
      "  File \"C:\\Users\\shema\\anaconda3\\lib\\asyncio\\selector_events.py\", line 115, in _read_from_self\n",
      "    data = self._ssock.recv(4096)\n",
      "ConnectionResetError: [WinError 10054] An existing connection was forcibly closed by the remote host\n",
      "Exception in callback BaseSelectorEventLoop._read_from_self()\n",
      "handle: <Handle BaseSelectorEventLoop._read_from_self()>\n",
      "Traceback (most recent call last):\n",
      "  File \"C:\\Users\\shema\\anaconda3\\lib\\asyncio\\events.py\", line 80, in _run\n",
      "    self._context.run(self._callback, *self._args)\n",
      "  File \"C:\\Users\\shema\\anaconda3\\lib\\asyncio\\selector_events.py\", line 115, in _read_from_self\n",
      "    data = self._ssock.recv(4096)\n",
      "ConnectionResetError: [WinError 10054] An existing connection was forcibly closed by the remote host\n",
      "Exception in callback BaseSelectorEventLoop._read_from_self()\n",
      "handle: <Handle BaseSelectorEventLoop._read_from_self()>\n",
      "Traceback (most recent call last):\n",
      "  File \"C:\\Users\\shema\\anaconda3\\lib\\asyncio\\events.py\", line 80, in _run\n",
      "    self._context.run(self._callback, *self._args)\n",
      "  File \"C:\\Users\\shema\\anaconda3\\lib\\asyncio\\selector_events.py\", line 115, in _read_from_self\n",
      "    data = self._ssock.recv(4096)\n",
      "ConnectionResetError: [WinError 10054] An existing connection was forcibly closed by the remote host\n",
      "Exception in callback BaseSelectorEventLoop._read_from_self()\n",
      "handle: <Handle BaseSelectorEventLoop._read_from_self()>\n",
      "Traceback (most recent call last):\n",
      "  File \"C:\\Users\\shema\\anaconda3\\lib\\asyncio\\events.py\", line 80, in _run\n",
      "    self._context.run(self._callback, *self._args)\n",
      "  File \"C:\\Users\\shema\\anaconda3\\lib\\asyncio\\selector_events.py\", line 115, in _read_from_self\n",
      "    data = self._ssock.recv(4096)\n",
      "ConnectionResetError: [WinError 10054] An existing connection was forcibly closed by the remote host\n",
      "Exception in callback BaseSelectorEventLoop._read_from_self()\n",
      "handle: <Handle BaseSelectorEventLoop._read_from_self()>\n",
      "Traceback (most recent call last):\n",
      "  File \"C:\\Users\\shema\\anaconda3\\lib\\asyncio\\events.py\", line 80, in _run\n",
      "    self._context.run(self._callback, *self._args)\n",
      "  File \"C:\\Users\\shema\\anaconda3\\lib\\asyncio\\selector_events.py\", line 115, in _read_from_self\n",
      "    data = self._ssock.recv(4096)\n",
      "ConnectionResetError: [WinError 10054] An existing connection was forcibly closed by the remote host\n",
      "Exception in callback BaseSelectorEventLoop._read_from_self()\n",
      "handle: <Handle BaseSelectorEventLoop._read_from_self()>\n",
      "Traceback (most recent call last):\n",
      "  File \"C:\\Users\\shema\\anaconda3\\lib\\asyncio\\events.py\", line 80, in _run\n",
      "    self._context.run(self._callback, *self._args)\n",
      "  File \"C:\\Users\\shema\\anaconda3\\lib\\asyncio\\selector_events.py\", line 115, in _read_from_self\n",
      "    data = self._ssock.recv(4096)\n",
      "ConnectionResetError: [WinError 10054] An existing connection was forcibly closed by the remote host\n",
      "Exception in callback BaseSelectorEventLoop._read_from_self()\n",
      "handle: <Handle BaseSelectorEventLoop._read_from_self()>\n",
      "Traceback (most recent call last):\n",
      "  File \"C:\\Users\\shema\\anaconda3\\lib\\asyncio\\events.py\", line 80, in _run\n",
      "    self._context.run(self._callback, *self._args)\n",
      "  File \"C:\\Users\\shema\\anaconda3\\lib\\asyncio\\selector_events.py\", line 115, in _read_from_self\n",
      "    data = self._ssock.recv(4096)\n",
      "ConnectionResetError: [WinError 10054] An existing connection was forcibly closed by the remote host\n",
      "Exception in callback BaseSelectorEventLoop._read_from_self()\n",
      "handle: <Handle BaseSelectorEventLoop._read_from_self()>\n",
      "Traceback (most recent call last):\n",
      "  File \"C:\\Users\\shema\\anaconda3\\lib\\asyncio\\events.py\", line 80, in _run\n",
      "    self._context.run(self._callback, *self._args)\n",
      "  File \"C:\\Users\\shema\\anaconda3\\lib\\asyncio\\selector_events.py\", line 115, in _read_from_self\n",
      "    data = self._ssock.recv(4096)\n",
      "ConnectionResetError: [WinError 10054] An existing connection was forcibly closed by the remote host\n",
      "Exception in callback BaseSelectorEventLoop._read_from_self()\n",
      "handle: <Handle BaseSelectorEventLoop._read_from_self()>\n",
      "Traceback (most recent call last):\n",
      "  File \"C:\\Users\\shema\\anaconda3\\lib\\asyncio\\events.py\", line 80, in _run\n",
      "    self._context.run(self._callback, *self._args)\n",
      "  File \"C:\\Users\\shema\\anaconda3\\lib\\asyncio\\selector_events.py\", line 115, in _read_from_self\n",
      "    data = self._ssock.recv(4096)\n",
      "ConnectionResetError: [WinError 10054] An existing connection was forcibly closed by the remote host\n",
      "Exception in callback BaseSelectorEventLoop._read_from_self()\n",
      "handle: <Handle BaseSelectorEventLoop._read_from_self()>\n",
      "Traceback (most recent call last):\n",
      "  File \"C:\\Users\\shema\\anaconda3\\lib\\asyncio\\events.py\", line 80, in _run\n",
      "    self._context.run(self._callback, *self._args)\n",
      "  File \"C:\\Users\\shema\\anaconda3\\lib\\asyncio\\selector_events.py\", line 115, in _read_from_self\n",
      "    data = self._ssock.recv(4096)\n",
      "ConnectionResetError: [WinError 10054] An existing connection was forcibly closed by the remote host\n",
      "Exception in callback BaseSelectorEventLoop._read_from_self()\n",
      "handle: <Handle BaseSelectorEventLoop._read_from_self()>\n",
      "Traceback (most recent call last):\n",
      "  File \"C:\\Users\\shema\\anaconda3\\lib\\asyncio\\events.py\", line 80, in _run\n",
      "    self._context.run(self._callback, *self._args)\n",
      "  File \"C:\\Users\\shema\\anaconda3\\lib\\asyncio\\selector_events.py\", line 115, in _read_from_self\n",
      "    data = self._ssock.recv(4096)\n",
      "ConnectionResetError: [WinError 10054] An existing connection was forcibly closed by the remote host\n",
      "Exception in callback BaseSelectorEventLoop._read_from_self()\n",
      "handle: <Handle BaseSelectorEventLoop._read_from_self()>\n",
      "Traceback (most recent call last):\n",
      "  File \"C:\\Users\\shema\\anaconda3\\lib\\asyncio\\events.py\", line 80, in _run\n",
      "    self._context.run(self._callback, *self._args)\n",
      "  File \"C:\\Users\\shema\\anaconda3\\lib\\asyncio\\selector_events.py\", line 115, in _read_from_self\n",
      "    data = self._ssock.recv(4096)\n",
      "ConnectionResetError: [WinError 10054] An existing connection was forcibly closed by the remote host\n",
      "Exception in callback BaseSelectorEventLoop._read_from_self()\n",
      "handle: <Handle BaseSelectorEventLoop._read_from_self()>\n",
      "Traceback (most recent call last):\n",
      "  File \"C:\\Users\\shema\\anaconda3\\lib\\asyncio\\events.py\", line 80, in _run\n",
      "    self._context.run(self._callback, *self._args)\n",
      "  File \"C:\\Users\\shema\\anaconda3\\lib\\asyncio\\selector_events.py\", line 115, in _read_from_self\n",
      "    data = self._ssock.recv(4096)\n",
      "ConnectionResetError: [WinError 10054] An existing connection was forcibly closed by the remote host\n",
      "Exception in callback BaseSelectorEventLoop._read_from_self()\n",
      "handle: <Handle BaseSelectorEventLoop._read_from_self()>\n",
      "Traceback (most recent call last):\n",
      "  File \"C:\\Users\\shema\\anaconda3\\lib\\asyncio\\events.py\", line 80, in _run\n",
      "    self._context.run(self._callback, *self._args)\n",
      "  File \"C:\\Users\\shema\\anaconda3\\lib\\asyncio\\selector_events.py\", line 115, in _read_from_self\n",
      "    data = self._ssock.recv(4096)\n",
      "ConnectionResetError: [WinError 10054] An existing connection was forcibly closed by the remote host\n",
      "Exception in callback BaseSelectorEventLoop._read_from_self()\n",
      "handle: <Handle BaseSelectorEventLoop._read_from_self()>\n",
      "Traceback (most recent call last):\n",
      "  File \"C:\\Users\\shema\\anaconda3\\lib\\asyncio\\events.py\", line 80, in _run\n",
      "    self._context.run(self._callback, *self._args)\n",
      "  File \"C:\\Users\\shema\\anaconda3\\lib\\asyncio\\selector_events.py\", line 115, in _read_from_self\n",
      "    data = self._ssock.recv(4096)\n",
      "ConnectionResetError: [WinError 10054] An existing connection was forcibly closed by the remote host\n",
      "Exception in callback BaseSelectorEventLoop._read_from_self()\n",
      "handle: <Handle BaseSelectorEventLoop._read_from_self()>\n",
      "Traceback (most recent call last):\n",
      "  File \"C:\\Users\\shema\\anaconda3\\lib\\asyncio\\events.py\", line 80, in _run\n",
      "    self._context.run(self._callback, *self._args)\n",
      "  File \"C:\\Users\\shema\\anaconda3\\lib\\asyncio\\selector_events.py\", line 115, in _read_from_self\n",
      "    data = self._ssock.recv(4096)\n",
      "ConnectionResetError: [WinError 10054] An existing connection was forcibly closed by the remote host\n",
      "Exception in callback BaseSelectorEventLoop._read_from_self()\n",
      "handle: <Handle BaseSelectorEventLoop._read_from_self()>\n",
      "Traceback (most recent call last):\n",
      "  File \"C:\\Users\\shema\\anaconda3\\lib\\asyncio\\events.py\", line 80, in _run\n",
      "    self._context.run(self._callback, *self._args)\n",
      "  File \"C:\\Users\\shema\\anaconda3\\lib\\asyncio\\selector_events.py\", line 115, in _read_from_self\n",
      "    data = self._ssock.recv(4096)\n",
      "ConnectionResetError: [WinError 10054] An existing connection was forcibly closed by the remote host\n",
      "Exception in callback BaseSelectorEventLoop._read_from_self()\n",
      "handle: <Handle BaseSelectorEventLoop._read_from_self()>\n",
      "Traceback (most recent call last):\n",
      "  File \"C:\\Users\\shema\\anaconda3\\lib\\asyncio\\events.py\", line 80, in _run\n",
      "    self._context.run(self._callback, *self._args)\n",
      "  File \"C:\\Users\\shema\\anaconda3\\lib\\asyncio\\selector_events.py\", line 115, in _read_from_self\n",
      "    data = self._ssock.recv(4096)\n",
      "ConnectionResetError: [WinError 10054] An existing connection was forcibly closed by the remote host\n",
      "Exception in callback BaseSelectorEventLoop._read_from_self()\n",
      "handle: <Handle BaseSelectorEventLoop._read_from_self()>\n",
      "Traceback (most recent call last):\n",
      "  File \"C:\\Users\\shema\\anaconda3\\lib\\asyncio\\events.py\", line 80, in _run\n",
      "    self._context.run(self._callback, *self._args)\n",
      "  File \"C:\\Users\\shema\\anaconda3\\lib\\asyncio\\selector_events.py\", line 115, in _read_from_self\n",
      "    data = self._ssock.recv(4096)\n",
      "ConnectionResetError: [WinError 10054] An existing connection was forcibly closed by the remote host\n",
      "Exception in callback BaseSelectorEventLoop._read_from_self()\n",
      "handle: <Handle BaseSelectorEventLoop._read_from_self()>\n",
      "Traceback (most recent call last):\n",
      "  File \"C:\\Users\\shema\\anaconda3\\lib\\asyncio\\events.py\", line 80, in _run\n",
      "    self._context.run(self._callback, *self._args)\n",
      "  File \"C:\\Users\\shema\\anaconda3\\lib\\asyncio\\selector_events.py\", line 115, in _read_from_self\n",
      "    data = self._ssock.recv(4096)\n",
      "ConnectionResetError: [WinError 10054] An existing connection was forcibly closed by the remote host\n",
      "Exception in callback BaseSelectorEventLoop._read_from_self()\n",
      "handle: <Handle BaseSelectorEventLoop._read_from_self()>\n",
      "Traceback (most recent call last):\n",
      "  File \"C:\\Users\\shema\\anaconda3\\lib\\asyncio\\events.py\", line 80, in _run\n",
      "    self._context.run(self._callback, *self._args)\n",
      "  File \"C:\\Users\\shema\\anaconda3\\lib\\asyncio\\selector_events.py\", line 115, in _read_from_self\n",
      "    data = self._ssock.recv(4096)\n",
      "ConnectionResetError: [WinError 10054] An existing connection was forcibly closed by the remote host\n",
      "Exception in callback BaseSelectorEventLoop._read_from_self()\n",
      "handle: <Handle BaseSelectorEventLoop._read_from_self()>\n",
      "Traceback (most recent call last):\n",
      "  File \"C:\\Users\\shema\\anaconda3\\lib\\asyncio\\events.py\", line 80, in _run\n",
      "    self._context.run(self._callback, *self._args)\n",
      "  File \"C:\\Users\\shema\\anaconda3\\lib\\asyncio\\selector_events.py\", line 115, in _read_from_self\n",
      "    data = self._ssock.recv(4096)\n",
      "ConnectionResetError: [WinError 10054] An existing connection was forcibly closed by the remote host\n",
      "Exception in callback BaseSelectorEventLoop._read_from_self()\n",
      "handle: <Handle BaseSelectorEventLoop._read_from_self()>\n",
      "Traceback (most recent call last):\n",
      "  File \"C:\\Users\\shema\\anaconda3\\lib\\asyncio\\events.py\", line 80, in _run\n",
      "    self._context.run(self._callback, *self._args)\n",
      "  File \"C:\\Users\\shema\\anaconda3\\lib\\asyncio\\selector_events.py\", line 115, in _read_from_self\n",
      "    data = self._ssock.recv(4096)\n",
      "ConnectionResetError: [WinError 10054] An existing connection was forcibly closed by the remote host\n",
      "Exception in callback BaseSelectorEventLoop._read_from_self()\n",
      "handle: <Handle BaseSelectorEventLoop._read_from_self()>\n",
      "Traceback (most recent call last):\n",
      "  File \"C:\\Users\\shema\\anaconda3\\lib\\asyncio\\events.py\", line 80, in _run\n",
      "    self._context.run(self._callback, *self._args)\n",
      "  File \"C:\\Users\\shema\\anaconda3\\lib\\asyncio\\selector_events.py\", line 115, in _read_from_self\n",
      "    data = self._ssock.recv(4096)\n",
      "ConnectionResetError: [WinError 10054] An existing connection was forcibly closed by the remote host\n",
      "Exception in callback BaseSelectorEventLoop._read_from_self()\n",
      "handle: <Handle BaseSelectorEventLoop._read_from_self()>\n",
      "Traceback (most recent call last):\n",
      "  File \"C:\\Users\\shema\\anaconda3\\lib\\asyncio\\events.py\", line 80, in _run\n",
      "    self._context.run(self._callback, *self._args)\n",
      "  File \"C:\\Users\\shema\\anaconda3\\lib\\asyncio\\selector_events.py\", line 115, in _read_from_self\n",
      "    data = self._ssock.recv(4096)\n",
      "ConnectionResetError: [WinError 10054] An existing connection was forcibly closed by the remote host\n",
      "Exception in callback BaseSelectorEventLoop._read_from_self()\n",
      "handle: <Handle BaseSelectorEventLoop._read_from_self()>\n",
      "Traceback (most recent call last):\n",
      "  File \"C:\\Users\\shema\\anaconda3\\lib\\asyncio\\events.py\", line 80, in _run\n",
      "    self._context.run(self._callback, *self._args)\n",
      "  File \"C:\\Users\\shema\\anaconda3\\lib\\asyncio\\selector_events.py\", line 115, in _read_from_self\n",
      "    data = self._ssock.recv(4096)\n",
      "ConnectionResetError: [WinError 10054] An existing connection was forcibly closed by the remote host\n",
      "Exception in callback BaseSelectorEventLoop._read_from_self()\n",
      "handle: <Handle BaseSelectorEventLoop._read_from_self()>\n",
      "Traceback (most recent call last):\n",
      "  File \"C:\\Users\\shema\\anaconda3\\lib\\asyncio\\events.py\", line 80, in _run\n",
      "    self._context.run(self._callback, *self._args)\n",
      "  File \"C:\\Users\\shema\\anaconda3\\lib\\asyncio\\selector_events.py\", line 115, in _read_from_self\n",
      "    data = self._ssock.recv(4096)\n",
      "ConnectionResetError: [WinError 10054] An existing connection was forcibly closed by the remote host\n",
      "Exception in callback BaseSelectorEventLoop._read_from_self()\n",
      "handle: <Handle BaseSelectorEventLoop._read_from_self()>\n",
      "Traceback (most recent call last):\n",
      "  File \"C:\\Users\\shema\\anaconda3\\lib\\asyncio\\events.py\", line 80, in _run\n",
      "    self._context.run(self._callback, *self._args)\n",
      "  File \"C:\\Users\\shema\\anaconda3\\lib\\asyncio\\selector_events.py\", line 115, in _read_from_self\n",
      "    data = self._ssock.recv(4096)\n",
      "ConnectionResetError: [WinError 10054] An existing connection was forcibly closed by the remote host\n",
      "Exception in callback BaseSelectorEventLoop._read_from_self()\n",
      "handle: <Handle BaseSelectorEventLoop._read_from_self()>\n",
      "Traceback (most recent call last):\n",
      "  File \"C:\\Users\\shema\\anaconda3\\lib\\asyncio\\events.py\", line 80, in _run\n",
      "    self._context.run(self._callback, *self._args)\n",
      "  File \"C:\\Users\\shema\\anaconda3\\lib\\asyncio\\selector_events.py\", line 115, in _read_from_self\n",
      "    data = self._ssock.recv(4096)\n",
      "ConnectionResetError: [WinError 10054] An existing connection was forcibly closed by the remote host\n",
      "Exception in callback BaseSelectorEventLoop._read_from_self()\n",
      "handle: <Handle BaseSelectorEventLoop._read_from_self()>\n",
      "Traceback (most recent call last):\n",
      "  File \"C:\\Users\\shema\\anaconda3\\lib\\asyncio\\events.py\", line 80, in _run\n",
      "    self._context.run(self._callback, *self._args)\n",
      "  File \"C:\\Users\\shema\\anaconda3\\lib\\asyncio\\selector_events.py\", line 115, in _read_from_self\n",
      "    data = self._ssock.recv(4096)\n",
      "ConnectionResetError: [WinError 10054] An existing connection was forcibly closed by the remote host\n",
      "Exception in callback BaseSelectorEventLoop._read_from_self()\n",
      "handle: <Handle BaseSelectorEventLoop._read_from_self()>\n",
      "Traceback (most recent call last):\n",
      "  File \"C:\\Users\\shema\\anaconda3\\lib\\asyncio\\events.py\", line 80, in _run\n",
      "    self._context.run(self._callback, *self._args)\n",
      "  File \"C:\\Users\\shema\\anaconda3\\lib\\asyncio\\selector_events.py\", line 115, in _read_from_self\n",
      "    data = self._ssock.recv(4096)\n",
      "ConnectionResetError: [WinError 10054] An existing connection was forcibly closed by the remote host\n",
      "Exception in callback BaseSelectorEventLoop._read_from_self()\n",
      "handle: <Handle BaseSelectorEventLoop._read_from_self()>\n",
      "Traceback (most recent call last):\n",
      "  File \"C:\\Users\\shema\\anaconda3\\lib\\asyncio\\events.py\", line 80, in _run\n",
      "    self._context.run(self._callback, *self._args)\n",
      "  File \"C:\\Users\\shema\\anaconda3\\lib\\asyncio\\selector_events.py\", line 115, in _read_from_self\n",
      "    data = self._ssock.recv(4096)\n",
      "ConnectionResetError: [WinError 10054] An existing connection was forcibly closed by the remote host\n",
      "Exception in callback BaseSelectorEventLoop._read_from_self()\n",
      "handle: <Handle BaseSelectorEventLoop._read_from_self()>\n",
      "Traceback (most recent call last):\n",
      "  File \"C:\\Users\\shema\\anaconda3\\lib\\asyncio\\events.py\", line 80, in _run\n",
      "    self._context.run(self._callback, *self._args)\n",
      "  File \"C:\\Users\\shema\\anaconda3\\lib\\asyncio\\selector_events.py\", line 115, in _read_from_self\n",
      "    data = self._ssock.recv(4096)\n",
      "ConnectionResetError: [WinError 10054] An existing connection was forcibly closed by the remote host\n",
      "Exception in callback BaseSelectorEventLoop._read_from_self()\n",
      "handle: <Handle BaseSelectorEventLoop._read_from_self()>\n",
      "Traceback (most recent call last):\n",
      "  File \"C:\\Users\\shema\\anaconda3\\lib\\asyncio\\events.py\", line 80, in _run\n",
      "    self._context.run(self._callback, *self._args)\n",
      "  File \"C:\\Users\\shema\\anaconda3\\lib\\asyncio\\selector_events.py\", line 115, in _read_from_self\n",
      "    data = self._ssock.recv(4096)\n",
      "ConnectionResetError: [WinError 10054] An existing connection was forcibly closed by the remote host\n",
      "Exception in callback BaseSelectorEventLoop._read_from_self()\n",
      "handle: <Handle BaseSelectorEventLoop._read_from_self()>\n",
      "Traceback (most recent call last):\n",
      "  File \"C:\\Users\\shema\\anaconda3\\lib\\asyncio\\events.py\", line 80, in _run\n",
      "    self._context.run(self._callback, *self._args)\n",
      "  File \"C:\\Users\\shema\\anaconda3\\lib\\asyncio\\selector_events.py\", line 115, in _read_from_self\n",
      "    data = self._ssock.recv(4096)\n",
      "ConnectionResetError: [WinError 10054] An existing connection was forcibly closed by the remote host\n",
      "Exception in callback BaseSelectorEventLoop._read_from_self()\n",
      "handle: <Handle BaseSelectorEventLoop._read_from_self()>\n",
      "Traceback (most recent call last):\n",
      "  File \"C:\\Users\\shema\\anaconda3\\lib\\asyncio\\events.py\", line 80, in _run\n",
      "    self._context.run(self._callback, *self._args)\n",
      "  File \"C:\\Users\\shema\\anaconda3\\lib\\asyncio\\selector_events.py\", line 115, in _read_from_self\n",
      "    data = self._ssock.recv(4096)\n",
      "ConnectionResetError: [WinError 10054] An existing connection was forcibly closed by the remote host\n",
      "Exception in callback BaseSelectorEventLoop._read_from_self()\n",
      "handle: <Handle BaseSelectorEventLoop._read_from_self()>\n",
      "Traceback (most recent call last):\n",
      "  File \"C:\\Users\\shema\\anaconda3\\lib\\asyncio\\events.py\", line 80, in _run\n",
      "    self._context.run(self._callback, *self._args)\n",
      "  File \"C:\\Users\\shema\\anaconda3\\lib\\asyncio\\selector_events.py\", line 115, in _read_from_self\n",
      "    data = self._ssock.recv(4096)\n",
      "ConnectionResetError: [WinError 10054] An existing connection was forcibly closed by the remote host\n",
      "Exception in callback BaseSelectorEventLoop._read_from_self()\n",
      "handle: <Handle BaseSelectorEventLoop._read_from_self()>\n",
      "Traceback (most recent call last):\n",
      "  File \"C:\\Users\\shema\\anaconda3\\lib\\asyncio\\events.py\", line 80, in _run\n",
      "    self._context.run(self._callback, *self._args)\n",
      "  File \"C:\\Users\\shema\\anaconda3\\lib\\asyncio\\selector_events.py\", line 115, in _read_from_self\n",
      "    data = self._ssock.recv(4096)\n",
      "ConnectionResetError: [WinError 10054] An existing connection was forcibly closed by the remote host\n",
      "Exception in callback BaseSelectorEventLoop._read_from_self()\n",
      "handle: <Handle BaseSelectorEventLoop._read_from_self()>\n",
      "Traceback (most recent call last):\n",
      "  File \"C:\\Users\\shema\\anaconda3\\lib\\asyncio\\events.py\", line 80, in _run\n",
      "    self._context.run(self._callback, *self._args)\n",
      "  File \"C:\\Users\\shema\\anaconda3\\lib\\asyncio\\selector_events.py\", line 115, in _read_from_self\n",
      "    data = self._ssock.recv(4096)\n",
      "ConnectionResetError: [WinError 10054] An existing connection was forcibly closed by the remote host\n",
      "Exception in callback BaseSelectorEventLoop._read_from_self()\n",
      "handle: <Handle BaseSelectorEventLoop._read_from_self()>\n",
      "Traceback (most recent call last):\n",
      "  File \"C:\\Users\\shema\\anaconda3\\lib\\asyncio\\events.py\", line 80, in _run\n",
      "    self._context.run(self._callback, *self._args)\n",
      "  File \"C:\\Users\\shema\\anaconda3\\lib\\asyncio\\selector_events.py\", line 115, in _read_from_self\n",
      "    data = self._ssock.recv(4096)\n",
      "ConnectionResetError: [WinError 10054] An existing connection was forcibly closed by the remote host\n",
      "Exception in callback BaseSelectorEventLoop._read_from_self()\n",
      "handle: <Handle BaseSelectorEventLoop._read_from_self()>\n",
      "Traceback (most recent call last):\n",
      "  File \"C:\\Users\\shema\\anaconda3\\lib\\asyncio\\events.py\", line 80, in _run\n",
      "    self._context.run(self._callback, *self._args)\n",
      "  File \"C:\\Users\\shema\\anaconda3\\lib\\asyncio\\selector_events.py\", line 115, in _read_from_self\n",
      "    data = self._ssock.recv(4096)\n",
      "ConnectionResetError: [WinError 10054] An existing connection was forcibly closed by the remote host\n",
      "Exception in callback BaseSelectorEventLoop._read_from_self()\n",
      "handle: <Handle BaseSelectorEventLoop._read_from_self()>\n",
      "Traceback (most recent call last):\n",
      "  File \"C:\\Users\\shema\\anaconda3\\lib\\asyncio\\events.py\", line 80, in _run\n",
      "    self._context.run(self._callback, *self._args)\n",
      "  File \"C:\\Users\\shema\\anaconda3\\lib\\asyncio\\selector_events.py\", line 115, in _read_from_self\n",
      "    data = self._ssock.recv(4096)\n",
      "ConnectionResetError: [WinError 10054] An existing connection was forcibly closed by the remote host\n",
      "Exception in callback BaseSelectorEventLoop._read_from_self()\n",
      "handle: <Handle BaseSelectorEventLoop._read_from_self()>\n",
      "Traceback (most recent call last):\n",
      "  File \"C:\\Users\\shema\\anaconda3\\lib\\asyncio\\events.py\", line 80, in _run\n",
      "    self._context.run(self._callback, *self._args)\n",
      "  File \"C:\\Users\\shema\\anaconda3\\lib\\asyncio\\selector_events.py\", line 115, in _read_from_self\n",
      "    data = self._ssock.recv(4096)\n",
      "ConnectionResetError: [WinError 10054] An existing connection was forcibly closed by the remote host\n",
      "Exception in callback BaseSelectorEventLoop._read_from_self()\n",
      "handle: <Handle BaseSelectorEventLoop._read_from_self()>\n",
      "Traceback (most recent call last):\n",
      "  File \"C:\\Users\\shema\\anaconda3\\lib\\asyncio\\events.py\", line 80, in _run\n",
      "    self._context.run(self._callback, *self._args)\n",
      "  File \"C:\\Users\\shema\\anaconda3\\lib\\asyncio\\selector_events.py\", line 115, in _read_from_self\n",
      "    data = self._ssock.recv(4096)\n",
      "ConnectionResetError: [WinError 10054] An existing connection was forcibly closed by the remote host\n",
      "Exception in callback BaseSelectorEventLoop._read_from_self()\n",
      "handle: <Handle BaseSelectorEventLoop._read_from_self()>\n",
      "Traceback (most recent call last):\n",
      "  File \"C:\\Users\\shema\\anaconda3\\lib\\asyncio\\events.py\", line 80, in _run\n",
      "    self._context.run(self._callback, *self._args)\n",
      "  File \"C:\\Users\\shema\\anaconda3\\lib\\asyncio\\selector_events.py\", line 115, in _read_from_self\n",
      "    data = self._ssock.recv(4096)\n",
      "ConnectionResetError: [WinError 10054] An existing connection was forcibly closed by the remote host\n",
      "Exception in callback BaseSelectorEventLoop._read_from_self()\n",
      "handle: <Handle BaseSelectorEventLoop._read_from_self()>\n",
      "Traceback (most recent call last):\n",
      "  File \"C:\\Users\\shema\\anaconda3\\lib\\asyncio\\events.py\", line 80, in _run\n",
      "    self._context.run(self._callback, *self._args)\n",
      "  File \"C:\\Users\\shema\\anaconda3\\lib\\asyncio\\selector_events.py\", line 115, in _read_from_self\n",
      "    data = self._ssock.recv(4096)\n",
      "ConnectionResetError: [WinError 10054] An existing connection was forcibly closed by the remote host\n",
      "Exception in callback BaseSelectorEventLoop._read_from_self()\n",
      "handle: <Handle BaseSelectorEventLoop._read_from_self()>\n",
      "Traceback (most recent call last):\n",
      "  File \"C:\\Users\\shema\\anaconda3\\lib\\asyncio\\events.py\", line 80, in _run\n",
      "    self._context.run(self._callback, *self._args)\n",
      "  File \"C:\\Users\\shema\\anaconda3\\lib\\asyncio\\selector_events.py\", line 115, in _read_from_self\n",
      "    data = self._ssock.recv(4096)\n",
      "ConnectionResetError: [WinError 10054] An existing connection was forcibly closed by the remote host\n",
      "Exception in callback BaseSelectorEventLoop._read_from_self()\n",
      "handle: <Handle BaseSelectorEventLoop._read_from_self()>\n",
      "Traceback (most recent call last):\n",
      "  File \"C:\\Users\\shema\\anaconda3\\lib\\asyncio\\events.py\", line 80, in _run\n",
      "    self._context.run(self._callback, *self._args)\n",
      "  File \"C:\\Users\\shema\\anaconda3\\lib\\asyncio\\selector_events.py\", line 115, in _read_from_self\n",
      "    data = self._ssock.recv(4096)\n",
      "ConnectionResetError: [WinError 10054] An existing connection was forcibly closed by the remote host\n",
      "Exception in callback BaseSelectorEventLoop._read_from_self()\n",
      "handle: <Handle BaseSelectorEventLoop._read_from_self()>\n",
      "Traceback (most recent call last):\n",
      "  File \"C:\\Users\\shema\\anaconda3\\lib\\asyncio\\events.py\", line 80, in _run\n",
      "    self._context.run(self._callback, *self._args)\n",
      "  File \"C:\\Users\\shema\\anaconda3\\lib\\asyncio\\selector_events.py\", line 115, in _read_from_self\n",
      "    data = self._ssock.recv(4096)\n",
      "ConnectionResetError: [WinError 10054] An existing connection was forcibly closed by the remote host\n",
      "Exception in callback BaseSelectorEventLoop._read_from_self()\n",
      "handle: <Handle BaseSelectorEventLoop._read_from_self()>\n",
      "Traceback (most recent call last):\n",
      "  File \"C:\\Users\\shema\\anaconda3\\lib\\asyncio\\events.py\", line 80, in _run\n",
      "    self._context.run(self._callback, *self._args)\n",
      "  File \"C:\\Users\\shema\\anaconda3\\lib\\asyncio\\selector_events.py\", line 115, in _read_from_self\n",
      "    data = self._ssock.recv(4096)\n",
      "ConnectionResetError: [WinError 10054] An existing connection was forcibly closed by the remote host\n",
      "Exception in callback BaseSelectorEventLoop._read_from_self()\n",
      "handle: <Handle BaseSelectorEventLoop._read_from_self()>\n",
      "Traceback (most recent call last):\n",
      "  File \"C:\\Users\\shema\\anaconda3\\lib\\asyncio\\events.py\", line 80, in _run\n",
      "    self._context.run(self._callback, *self._args)\n",
      "  File \"C:\\Users\\shema\\anaconda3\\lib\\asyncio\\selector_events.py\", line 115, in _read_from_self\n",
      "    data = self._ssock.recv(4096)\n",
      "ConnectionResetError: [WinError 10054] An existing connection was forcibly closed by the remote host\n",
      "Exception in callback BaseSelectorEventLoop._read_from_self()\n",
      "handle: <Handle BaseSelectorEventLoop._read_from_self()>\n",
      "Traceback (most recent call last):\n",
      "  File \"C:\\Users\\shema\\anaconda3\\lib\\asyncio\\events.py\", line 80, in _run\n",
      "    self._context.run(self._callback, *self._args)\n",
      "  File \"C:\\Users\\shema\\anaconda3\\lib\\asyncio\\selector_events.py\", line 115, in _read_from_self\n",
      "    data = self._ssock.recv(4096)\n",
      "ConnectionResetError: [WinError 10054] An existing connection was forcibly closed by the remote host\n",
      "Exception in callback BaseSelectorEventLoop._read_from_self()\n",
      "handle: <Handle BaseSelectorEventLoop._read_from_self()>\n",
      "Traceback (most recent call last):\n",
      "  File \"C:\\Users\\shema\\anaconda3\\lib\\asyncio\\events.py\", line 80, in _run\n",
      "    self._context.run(self._callback, *self._args)\n",
      "  File \"C:\\Users\\shema\\anaconda3\\lib\\asyncio\\selector_events.py\", line 115, in _read_from_self\n",
      "    data = self._ssock.recv(4096)\n",
      "ConnectionResetError: [WinError 10054] An existing connection was forcibly closed by the remote host\n",
      "Exception in callback BaseSelectorEventLoop._read_from_self()\n",
      "handle: <Handle BaseSelectorEventLoop._read_from_self()>\n",
      "Traceback (most recent call last):\n",
      "  File \"C:\\Users\\shema\\anaconda3\\lib\\asyncio\\events.py\", line 80, in _run\n",
      "    self._context.run(self._callback, *self._args)\n",
      "  File \"C:\\Users\\shema\\anaconda3\\lib\\asyncio\\selector_events.py\", line 115, in _read_from_self\n",
      "    data = self._ssock.recv(4096)\n",
      "ConnectionResetError: [WinError 10054] An existing connection was forcibly closed by the remote host\n",
      "Exception in callback BaseSelectorEventLoop._read_from_self()\n",
      "handle: <Handle BaseSelectorEventLoop._read_from_self()>\n",
      "Traceback (most recent call last):\n",
      "  File \"C:\\Users\\shema\\anaconda3\\lib\\asyncio\\events.py\", line 80, in _run\n",
      "    self._context.run(self._callback, *self._args)\n",
      "  File \"C:\\Users\\shema\\anaconda3\\lib\\asyncio\\selector_events.py\", line 115, in _read_from_self\n",
      "    data = self._ssock.recv(4096)\n",
      "ConnectionResetError: [WinError 10054] An existing connection was forcibly closed by the remote host\n",
      "Exception in callback BaseSelectorEventLoop._read_from_self()\n",
      "handle: <Handle BaseSelectorEventLoop._read_from_self()>\n",
      "Traceback (most recent call last):\n",
      "  File \"C:\\Users\\shema\\anaconda3\\lib\\asyncio\\events.py\", line 80, in _run\n",
      "    self._context.run(self._callback, *self._args)\n",
      "  File \"C:\\Users\\shema\\anaconda3\\lib\\asyncio\\selector_events.py\", line 115, in _read_from_self\n",
      "    data = self._ssock.recv(4096)\n",
      "ConnectionResetError: [WinError 10054] An existing connection was forcibly closed by the remote host\n",
      "Exception in callback BaseSelectorEventLoop._read_from_self()\n",
      "handle: <Handle BaseSelectorEventLoop._read_from_self()>\n",
      "Traceback (most recent call last):\n",
      "  File \"C:\\Users\\shema\\anaconda3\\lib\\asyncio\\events.py\", line 80, in _run\n",
      "    self._context.run(self._callback, *self._args)\n",
      "  File \"C:\\Users\\shema\\anaconda3\\lib\\asyncio\\selector_events.py\", line 115, in _read_from_self\n",
      "    data = self._ssock.recv(4096)\n",
      "ConnectionResetError: [WinError 10054] An existing connection was forcibly closed by the remote host\n",
      "Exception in callback BaseSelectorEventLoop._read_from_self()\n",
      "handle: <Handle BaseSelectorEventLoop._read_from_self()>\n",
      "Traceback (most recent call last):\n",
      "  File \"C:\\Users\\shema\\anaconda3\\lib\\asyncio\\events.py\", line 80, in _run\n",
      "    self._context.run(self._callback, *self._args)\n",
      "  File \"C:\\Users\\shema\\anaconda3\\lib\\asyncio\\selector_events.py\", line 115, in _read_from_self\n",
      "    data = self._ssock.recv(4096)\n",
      "ConnectionResetError: [WinError 10054] An existing connection was forcibly closed by the remote host\n",
      "Exception in callback BaseSelectorEventLoop._read_from_self()\n",
      "handle: <Handle BaseSelectorEventLoop._read_from_self()>\n",
      "Traceback (most recent call last):\n",
      "  File \"C:\\Users\\shema\\anaconda3\\lib\\asyncio\\events.py\", line 80, in _run\n",
      "    self._context.run(self._callback, *self._args)\n",
      "  File \"C:\\Users\\shema\\anaconda3\\lib\\asyncio\\selector_events.py\", line 115, in _read_from_self\n",
      "    data = self._ssock.recv(4096)\n",
      "ConnectionResetError: [WinError 10054] An existing connection was forcibly closed by the remote host\n",
      "Exception in callback BaseSelectorEventLoop._read_from_self()\n",
      "handle: <Handle BaseSelectorEventLoop._read_from_self()>\n",
      "Traceback (most recent call last):\n",
      "  File \"C:\\Users\\shema\\anaconda3\\lib\\asyncio\\events.py\", line 80, in _run\n",
      "    self._context.run(self._callback, *self._args)\n",
      "  File \"C:\\Users\\shema\\anaconda3\\lib\\asyncio\\selector_events.py\", line 115, in _read_from_self\n",
      "    data = self._ssock.recv(4096)\n",
      "ConnectionResetError: [WinError 10054] An existing connection was forcibly closed by the remote host\n",
      "Exception in callback BaseSelectorEventLoop._read_from_self()\n",
      "handle: <Handle BaseSelectorEventLoop._read_from_self()>\n",
      "Traceback (most recent call last):\n",
      "  File \"C:\\Users\\shema\\anaconda3\\lib\\asyncio\\events.py\", line 80, in _run\n",
      "    self._context.run(self._callback, *self._args)\n",
      "  File \"C:\\Users\\shema\\anaconda3\\lib\\asyncio\\selector_events.py\", line 115, in _read_from_self\n",
      "    data = self._ssock.recv(4096)\n",
      "ConnectionResetError: [WinError 10054] An existing connection was forcibly closed by the remote host\n",
      "Exception in callback BaseSelectorEventLoop._read_from_self()\n",
      "handle: <Handle BaseSelectorEventLoop._read_from_self()>\n",
      "Traceback (most recent call last):\n",
      "  File \"C:\\Users\\shema\\anaconda3\\lib\\asyncio\\events.py\", line 80, in _run\n",
      "    self._context.run(self._callback, *self._args)\n",
      "  File \"C:\\Users\\shema\\anaconda3\\lib\\asyncio\\selector_events.py\", line 115, in _read_from_self\n",
      "    data = self._ssock.recv(4096)\n",
      "ConnectionResetError: [WinError 10054] An existing connection was forcibly closed by the remote host\n",
      "Exception in callback BaseSelectorEventLoop._read_from_self()\n",
      "handle: <Handle BaseSelectorEventLoop._read_from_self()>\n",
      "Traceback (most recent call last):\n",
      "  File \"C:\\Users\\shema\\anaconda3\\lib\\asyncio\\events.py\", line 80, in _run\n",
      "    self._context.run(self._callback, *self._args)\n",
      "  File \"C:\\Users\\shema\\anaconda3\\lib\\asyncio\\selector_events.py\", line 115, in _read_from_self\n",
      "    data = self._ssock.recv(4096)\n",
      "ConnectionResetError: [WinError 10054] An existing connection was forcibly closed by the remote host\n",
      "Exception in callback BaseSelectorEventLoop._read_from_self()\n",
      "handle: <Handle BaseSelectorEventLoop._read_from_self()>\n",
      "Traceback (most recent call last):\n",
      "  File \"C:\\Users\\shema\\anaconda3\\lib\\asyncio\\events.py\", line 80, in _run\n",
      "    self._context.run(self._callback, *self._args)\n",
      "  File \"C:\\Users\\shema\\anaconda3\\lib\\asyncio\\selector_events.py\", line 115, in _read_from_self\n",
      "    data = self._ssock.recv(4096)\n",
      "ConnectionResetError: [WinError 10054] An existing connection was forcibly closed by the remote host\n",
      "Exception in callback BaseSelectorEventLoop._read_from_self()\n",
      "handle: <Handle BaseSelectorEventLoop._read_from_self()>\n",
      "Traceback (most recent call last):\n",
      "  File \"C:\\Users\\shema\\anaconda3\\lib\\asyncio\\events.py\", line 80, in _run\n",
      "    self._context.run(self._callback, *self._args)\n",
      "  File \"C:\\Users\\shema\\anaconda3\\lib\\asyncio\\selector_events.py\", line 115, in _read_from_self\n",
      "    data = self._ssock.recv(4096)\n",
      "ConnectionResetError: [WinError 10054] An existing connection was forcibly closed by the remote host\n",
      "Exception in callback BaseSelectorEventLoop._read_from_self()\n",
      "handle: <Handle BaseSelectorEventLoop._read_from_self()>\n",
      "Traceback (most recent call last):\n",
      "  File \"C:\\Users\\shema\\anaconda3\\lib\\asyncio\\events.py\", line 80, in _run\n",
      "    self._context.run(self._callback, *self._args)\n",
      "  File \"C:\\Users\\shema\\anaconda3\\lib\\asyncio\\selector_events.py\", line 115, in _read_from_self\n",
      "    data = self._ssock.recv(4096)\n",
      "ConnectionResetError: [WinError 10054] An existing connection was forcibly closed by the remote host\n",
      "Exception in callback BaseSelectorEventLoop._read_from_self()\n",
      "handle: <Handle BaseSelectorEventLoop._read_from_self()>\n",
      "Traceback (most recent call last):\n",
      "  File \"C:\\Users\\shema\\anaconda3\\lib\\asyncio\\events.py\", line 80, in _run\n",
      "    self._context.run(self._callback, *self._args)\n",
      "  File \"C:\\Users\\shema\\anaconda3\\lib\\asyncio\\selector_events.py\", line 115, in _read_from_self\n",
      "    data = self._ssock.recv(4096)\n",
      "ConnectionResetError: [WinError 10054] An existing connection was forcibly closed by the remote host\n",
      "Exception in callback BaseSelectorEventLoop._read_from_self()\n",
      "handle: <Handle BaseSelectorEventLoop._read_from_self()>\n",
      "Traceback (most recent call last):\n",
      "  File \"C:\\Users\\shema\\anaconda3\\lib\\asyncio\\events.py\", line 80, in _run\n",
      "    self._context.run(self._callback, *self._args)\n",
      "  File \"C:\\Users\\shema\\anaconda3\\lib\\asyncio\\selector_events.py\", line 115, in _read_from_self\n",
      "    data = self._ssock.recv(4096)\n",
      "ConnectionResetError: [WinError 10054] An existing connection was forcibly closed by the remote host\n",
      "Exception in callback BaseSelectorEventLoop._read_from_self()\n",
      "handle: <Handle BaseSelectorEventLoop._read_from_self()>\n",
      "Traceback (most recent call last):\n",
      "  File \"C:\\Users\\shema\\anaconda3\\lib\\asyncio\\events.py\", line 80, in _run\n",
      "    self._context.run(self._callback, *self._args)\n",
      "  File \"C:\\Users\\shema\\anaconda3\\lib\\asyncio\\selector_events.py\", line 115, in _read_from_self\n",
      "    data = self._ssock.recv(4096)\n",
      "ConnectionResetError: [WinError 10054] An existing connection was forcibly closed by the remote host\n",
      "Exception in callback BaseSelectorEventLoop._read_from_self()\n",
      "handle: <Handle BaseSelectorEventLoop._read_from_self()>\n",
      "Traceback (most recent call last):\n",
      "  File \"C:\\Users\\shema\\anaconda3\\lib\\asyncio\\events.py\", line 80, in _run\n",
      "    self._context.run(self._callback, *self._args)\n",
      "  File \"C:\\Users\\shema\\anaconda3\\lib\\asyncio\\selector_events.py\", line 115, in _read_from_self\n",
      "    data = self._ssock.recv(4096)\n",
      "ConnectionResetError: [WinError 10054] An existing connection was forcibly closed by the remote host\n",
      "Exception in callback BaseSelectorEventLoop._read_from_self()\n",
      "handle: <Handle BaseSelectorEventLoop._read_from_self()>\n",
      "Traceback (most recent call last):\n",
      "  File \"C:\\Users\\shema\\anaconda3\\lib\\asyncio\\events.py\", line 80, in _run\n",
      "    self._context.run(self._callback, *self._args)\n",
      "  File \"C:\\Users\\shema\\anaconda3\\lib\\asyncio\\selector_events.py\", line 115, in _read_from_self\n",
      "    data = self._ssock.recv(4096)\n",
      "ConnectionResetError: [WinError 10054] An existing connection was forcibly closed by the remote host\n",
      "Exception in callback BaseSelectorEventLoop._read_from_self()\n",
      "handle: <Handle BaseSelectorEventLoop._read_from_self()>\n",
      "Traceback (most recent call last):\n",
      "  File \"C:\\Users\\shema\\anaconda3\\lib\\asyncio\\events.py\", line 80, in _run\n",
      "    self._context.run(self._callback, *self._args)\n",
      "  File \"C:\\Users\\shema\\anaconda3\\lib\\asyncio\\selector_events.py\", line 115, in _read_from_self\n",
      "    data = self._ssock.recv(4096)\n",
      "ConnectionResetError: [WinError 10054] An existing connection was forcibly closed by the remote host\n",
      "Exception in callback BaseSelectorEventLoop._read_from_self()\n",
      "handle: <Handle BaseSelectorEventLoop._read_from_self()>\n",
      "Traceback (most recent call last):\n",
      "  File \"C:\\Users\\shema\\anaconda3\\lib\\asyncio\\events.py\", line 80, in _run\n",
      "    self._context.run(self._callback, *self._args)\n",
      "  File \"C:\\Users\\shema\\anaconda3\\lib\\asyncio\\selector_events.py\", line 115, in _read_from_self\n",
      "    data = self._ssock.recv(4096)\n",
      "ConnectionResetError: [WinError 10054] An existing connection was forcibly closed by the remote host\n",
      "Exception in callback BaseSelectorEventLoop._read_from_self()\n",
      "handle: <Handle BaseSelectorEventLoop._read_from_self()>\n",
      "Traceback (most recent call last):\n",
      "  File \"C:\\Users\\shema\\anaconda3\\lib\\asyncio\\events.py\", line 80, in _run\n",
      "    self._context.run(self._callback, *self._args)\n",
      "  File \"C:\\Users\\shema\\anaconda3\\lib\\asyncio\\selector_events.py\", line 115, in _read_from_self\n",
      "    data = self._ssock.recv(4096)\n",
      "ConnectionResetError: [WinError 10054] An existing connection was forcibly closed by the remote host\n",
      "Exception in callback BaseSelectorEventLoop._read_from_self()\n",
      "handle: <Handle BaseSelectorEventLoop._read_from_self()>\n",
      "Traceback (most recent call last):\n",
      "  File \"C:\\Users\\shema\\anaconda3\\lib\\asyncio\\events.py\", line 80, in _run\n",
      "    self._context.run(self._callback, *self._args)\n",
      "  File \"C:\\Users\\shema\\anaconda3\\lib\\asyncio\\selector_events.py\", line 115, in _read_from_self\n",
      "    data = self._ssock.recv(4096)\n",
      "ConnectionResetError: [WinError 10054] An existing connection was forcibly closed by the remote host\n",
      "Exception in callback BaseSelectorEventLoop._read_from_self()\n",
      "handle: <Handle BaseSelectorEventLoop._read_from_self()>\n",
      "Traceback (most recent call last):\n",
      "  File \"C:\\Users\\shema\\anaconda3\\lib\\asyncio\\events.py\", line 80, in _run\n",
      "    self._context.run(self._callback, *self._args)\n",
      "  File \"C:\\Users\\shema\\anaconda3\\lib\\asyncio\\selector_events.py\", line 115, in _read_from_self\n",
      "    data = self._ssock.recv(4096)\n",
      "ConnectionResetError: [WinError 10054] An existing connection was forcibly closed by the remote host\n",
      "Exception in callback BaseSelectorEventLoop._read_from_self()\n",
      "handle: <Handle BaseSelectorEventLoop._read_from_self()>\n",
      "Traceback (most recent call last):\n",
      "  File \"C:\\Users\\shema\\anaconda3\\lib\\asyncio\\events.py\", line 80, in _run\n",
      "    self._context.run(self._callback, *self._args)\n",
      "  File \"C:\\Users\\shema\\anaconda3\\lib\\asyncio\\selector_events.py\", line 115, in _read_from_self\n",
      "    data = self._ssock.recv(4096)\n",
      "ConnectionResetError: [WinError 10054] An existing connection was forcibly closed by the remote host\n",
      "Exception in callback BaseSelectorEventLoop._read_from_self()\n",
      "handle: <Handle BaseSelectorEventLoop._read_from_self()>\n",
      "Traceback (most recent call last):\n",
      "  File \"C:\\Users\\shema\\anaconda3\\lib\\asyncio\\events.py\", line 80, in _run\n",
      "    self._context.run(self._callback, *self._args)\n",
      "  File \"C:\\Users\\shema\\anaconda3\\lib\\asyncio\\selector_events.py\", line 115, in _read_from_self\n",
      "    data = self._ssock.recv(4096)\n",
      "ConnectionResetError: [WinError 10054] An existing connection was forcibly closed by the remote host\n",
      "Exception in callback BaseSelectorEventLoop._read_from_self()\n",
      "handle: <Handle BaseSelectorEventLoop._read_from_self()>\n",
      "Traceback (most recent call last):\n",
      "  File \"C:\\Users\\shema\\anaconda3\\lib\\asyncio\\events.py\", line 80, in _run\n",
      "    self._context.run(self._callback, *self._args)\n",
      "  File \"C:\\Users\\shema\\anaconda3\\lib\\asyncio\\selector_events.py\", line 115, in _read_from_self\n",
      "    data = self._ssock.recv(4096)\n",
      "ConnectionResetError: [WinError 10054] An existing connection was forcibly closed by the remote host\n",
      "Exception in callback BaseSelectorEventLoop._read_from_self()\n",
      "handle: <Handle BaseSelectorEventLoop._read_from_self()>\n",
      "Traceback (most recent call last):\n",
      "  File \"C:\\Users\\shema\\anaconda3\\lib\\asyncio\\events.py\", line 80, in _run\n",
      "    self._context.run(self._callback, *self._args)\n",
      "  File \"C:\\Users\\shema\\anaconda3\\lib\\asyncio\\selector_events.py\", line 115, in _read_from_self\n",
      "    data = self._ssock.recv(4096)\n",
      "ConnectionResetError: [WinError 10054] An existing connection was forcibly closed by the remote host\n",
      "Exception in callback BaseSelectorEventLoop._read_from_self()\n",
      "handle: <Handle BaseSelectorEventLoop._read_from_self()>\n",
      "Traceback (most recent call last):\n",
      "  File \"C:\\Users\\shema\\anaconda3\\lib\\asyncio\\events.py\", line 80, in _run\n",
      "    self._context.run(self._callback, *self._args)\n",
      "  File \"C:\\Users\\shema\\anaconda3\\lib\\asyncio\\selector_events.py\", line 115, in _read_from_self\n",
      "    data = self._ssock.recv(4096)\n",
      "ConnectionResetError: [WinError 10054] An existing connection was forcibly closed by the remote host\n",
      "Exception in callback BaseSelectorEventLoop._read_from_self()\n",
      "handle: <Handle BaseSelectorEventLoop._read_from_self()>\n",
      "Traceback (most recent call last):\n",
      "  File \"C:\\Users\\shema\\anaconda3\\lib\\asyncio\\events.py\", line 80, in _run\n",
      "    self._context.run(self._callback, *self._args)\n",
      "  File \"C:\\Users\\shema\\anaconda3\\lib\\asyncio\\selector_events.py\", line 115, in _read_from_self\n",
      "    data = self._ssock.recv(4096)\n",
      "ConnectionResetError: [WinError 10054] An existing connection was forcibly closed by the remote host\n",
      "Exception in callback BaseSelectorEventLoop._read_from_self()\n",
      "handle: <Handle BaseSelectorEventLoop._read_from_self()>\n",
      "Traceback (most recent call last):\n",
      "  File \"C:\\Users\\shema\\anaconda3\\lib\\asyncio\\events.py\", line 80, in _run\n",
      "    self._context.run(self._callback, *self._args)\n",
      "  File \"C:\\Users\\shema\\anaconda3\\lib\\asyncio\\selector_events.py\", line 115, in _read_from_self\n",
      "    data = self._ssock.recv(4096)\n",
      "ConnectionResetError: [WinError 10054] An existing connection was forcibly closed by the remote host\n",
      "Exception in callback BaseSelectorEventLoop._read_from_self()\n",
      "handle: <Handle BaseSelectorEventLoop._read_from_self()>\n",
      "Traceback (most recent call last):\n",
      "  File \"C:\\Users\\shema\\anaconda3\\lib\\asyncio\\events.py\", line 80, in _run\n",
      "    self._context.run(self._callback, *self._args)\n",
      "  File \"C:\\Users\\shema\\anaconda3\\lib\\asyncio\\selector_events.py\", line 115, in _read_from_self\n",
      "    data = self._ssock.recv(4096)\n",
      "ConnectionResetError: [WinError 10054] An existing connection was forcibly closed by the remote host\n",
      "Exception in callback BaseSelectorEventLoop._read_from_self()\n",
      "handle: <Handle BaseSelectorEventLoop._read_from_self()>\n",
      "Traceback (most recent call last):\n",
      "  File \"C:\\Users\\shema\\anaconda3\\lib\\asyncio\\events.py\", line 80, in _run\n",
      "    self._context.run(self._callback, *self._args)\n",
      "  File \"C:\\Users\\shema\\anaconda3\\lib\\asyncio\\selector_events.py\", line 115, in _read_from_self\n",
      "    data = self._ssock.recv(4096)\n",
      "ConnectionResetError: [WinError 10054] An existing connection was forcibly closed by the remote host\n",
      "Exception in callback BaseSelectorEventLoop._read_from_self()\n",
      "handle: <Handle BaseSelectorEventLoop._read_from_self()>\n",
      "Traceback (most recent call last):\n",
      "  File \"C:\\Users\\shema\\anaconda3\\lib\\asyncio\\events.py\", line 80, in _run\n",
      "    self._context.run(self._callback, *self._args)\n",
      "  File \"C:\\Users\\shema\\anaconda3\\lib\\asyncio\\selector_events.py\", line 115, in _read_from_self\n",
      "    data = self._ssock.recv(4096)\n",
      "ConnectionResetError: [WinError 10054] An existing connection was forcibly closed by the remote host\n",
      "Exception in callback BaseSelectorEventLoop._read_from_self()\n",
      "handle: <Handle BaseSelectorEventLoop._read_from_self()>\n",
      "Traceback (most recent call last):\n",
      "  File \"C:\\Users\\shema\\anaconda3\\lib\\asyncio\\events.py\", line 80, in _run\n",
      "    self._context.run(self._callback, *self._args)\n",
      "  File \"C:\\Users\\shema\\anaconda3\\lib\\asyncio\\selector_events.py\", line 115, in _read_from_self\n",
      "    data = self._ssock.recv(4096)\n",
      "ConnectionResetError: [WinError 10054] An existing connection was forcibly closed by the remote host\n",
      "Exception in callback BaseSelectorEventLoop._read_from_self()\n",
      "handle: <Handle BaseSelectorEventLoop._read_from_self()>\n",
      "Traceback (most recent call last):\n",
      "  File \"C:\\Users\\shema\\anaconda3\\lib\\asyncio\\events.py\", line 80, in _run\n",
      "    self._context.run(self._callback, *self._args)\n",
      "  File \"C:\\Users\\shema\\anaconda3\\lib\\asyncio\\selector_events.py\", line 115, in _read_from_self\n",
      "    data = self._ssock.recv(4096)\n",
      "ConnectionResetError: [WinError 10054] An existing connection was forcibly closed by the remote host\n",
      "Exception in callback BaseSelectorEventLoop._read_from_self()\n",
      "handle: <Handle BaseSelectorEventLoop._read_from_self()>\n",
      "Traceback (most recent call last):\n",
      "  File \"C:\\Users\\shema\\anaconda3\\lib\\asyncio\\events.py\", line 80, in _run\n",
      "    self._context.run(self._callback, *self._args)\n",
      "  File \"C:\\Users\\shema\\anaconda3\\lib\\asyncio\\selector_events.py\", line 115, in _read_from_self\n",
      "    data = self._ssock.recv(4096)\n",
      "ConnectionResetError: [WinError 10054] An existing connection was forcibly closed by the remote host\n",
      "Exception in callback BaseSelectorEventLoop._read_from_self()\n",
      "handle: <Handle BaseSelectorEventLoop._read_from_self()>\n",
      "Traceback (most recent call last):\n",
      "  File \"C:\\Users\\shema\\anaconda3\\lib\\asyncio\\events.py\", line 80, in _run\n",
      "    self._context.run(self._callback, *self._args)\n",
      "  File \"C:\\Users\\shema\\anaconda3\\lib\\asyncio\\selector_events.py\", line 115, in _read_from_self\n",
      "    data = self._ssock.recv(4096)\n",
      "ConnectionResetError: [WinError 10054] An existing connection was forcibly closed by the remote host\n",
      "Exception in callback BaseSelectorEventLoop._read_from_self()\n",
      "handle: <Handle BaseSelectorEventLoop._read_from_self()>\n",
      "Traceback (most recent call last):\n",
      "  File \"C:\\Users\\shema\\anaconda3\\lib\\asyncio\\events.py\", line 80, in _run\n",
      "    self._context.run(self._callback, *self._args)\n",
      "  File \"C:\\Users\\shema\\anaconda3\\lib\\asyncio\\selector_events.py\", line 115, in _read_from_self\n",
      "    data = self._ssock.recv(4096)\n",
      "ConnectionResetError: [WinError 10054] An existing connection was forcibly closed by the remote host\n",
      "Exception in callback BaseSelectorEventLoop._read_from_self()\n",
      "handle: <Handle BaseSelectorEventLoop._read_from_self()>\n",
      "Traceback (most recent call last):\n",
      "  File \"C:\\Users\\shema\\anaconda3\\lib\\asyncio\\events.py\", line 80, in _run\n",
      "    self._context.run(self._callback, *self._args)\n",
      "  File \"C:\\Users\\shema\\anaconda3\\lib\\asyncio\\selector_events.py\", line 115, in _read_from_self\n",
      "    data = self._ssock.recv(4096)\n",
      "ConnectionResetError: [WinError 10054] An existing connection was forcibly closed by the remote host\n",
      "Exception in callback BaseSelectorEventLoop._read_from_self()\n",
      "handle: <Handle BaseSelectorEventLoop._read_from_self()>\n",
      "Traceback (most recent call last):\n",
      "  File \"C:\\Users\\shema\\anaconda3\\lib\\asyncio\\events.py\", line 80, in _run\n",
      "    self._context.run(self._callback, *self._args)\n",
      "  File \"C:\\Users\\shema\\anaconda3\\lib\\asyncio\\selector_events.py\", line 115, in _read_from_self\n",
      "    data = self._ssock.recv(4096)\n",
      "ConnectionResetError: [WinError 10054] An existing connection was forcibly closed by the remote host\n"
     ]
    }
   ],
   "source": [
    "data.head()"
   ]
  },
  {
   "cell_type": "code",
   "execution_count": null,
   "id": "94c86537",
   "metadata": {},
   "outputs": [],
   "source": []
  },
  {
   "cell_type": "code",
   "execution_count": null,
   "id": "c7796892",
   "metadata": {},
   "outputs": [],
   "source": []
  }
 ],
 "metadata": {
  "kernelspec": {
   "display_name": "Python 3 (ipykernel)",
   "language": "python",
   "name": "python3"
  },
  "language_info": {
   "codemirror_mode": {
    "name": "ipython",
    "version": 3
   },
   "file_extension": ".py",
   "mimetype": "text/x-python",
   "name": "python",
   "nbconvert_exporter": "python",
   "pygments_lexer": "ipython3",
   "version": "3.10.5"
  }
 },
 "nbformat": 4,
 "nbformat_minor": 5
}
